Workbook

Sheet Rates from Ireland Fedex Priort
A1: Type | B1: Ship From | C1: Ship To | D1: Doc 0.5kg | E1: Paket 1kg | F1: Paket 2kg | G1: Box 5kg | H1: Box 10kg | I1: Box 15kg | J1: Box 20kg | K1: Box 25kg | L1: Suitcase 10kg | M1: Suitcase 20kg | N1: Suitcase 30kg | O1: Days ENV | P1: Days PARCEL | Q1: Insurance | R1: Rating | S1: Courier | T1: Service
A2: EU | B2: Ireland | C2: Afghanistan | D2: No service | E2: No service | F2: No service | G2: No service | H2: No service | I2: No service | J2: No service | K2: No service | L2: No service | M2: No service | N2: No service
A3: EU | B3: Ireland | C3: Albania | D3: 35.5 | E3: 44.375 | F3: 47.375 | G3: 56.875 | H3: 61.25 | I3: 68.75 | J3: No service | K3: No service | L3: No service | M3: No service | N3: No service | O3: 8 Days | P3: 9 Days | Q3: 80 | R3: 4/5* | S3: FedEx Prioirty | T3: Priority
A4: EU | B4: Ireland | C4: Algeria | D4: 21.06 | E4: 28.075 | F4: 31.6625 | G4: 45.05 | H4: 70.35 | I4: 133.225 | J4: No service | K4: No service | L4: No service | M4: No service | N4: No service | O4: 3 Days | P4: 3-4 Days | Q4: 80 | R4: 4/5* | S4: FedEx Prioirty | T4: Priority
A5: EU | B5: Ireland | C5: American Samoa (US) | D5: 31.72 | E5: 42.1875 | F5: 47.375 | G5: 65.45 | H5: No service | I5: No service | J5: No service | K5: No service | L5: No service | M5: No service | N5: No service | S5: FedEx Prioirty | T5: Priority
A6: EU | B6: Ireland | C6: Andorra | D6: 23 | E6: 24.625 | F6: 25 | G6: 26.25 | H6: 30.625 | I6: 37.5 | J6: No service | K6: No service | L6: No service | M6: No service | N6: No service | O6: 6 Days | P6: 8 Days | Q6: 80 | R6: 4/5* | S6: FedEx Prioirty | T6: Priority
A7: EU | B7: Ireland | C7: Angola | D7: 31.72 | E7: 42.1875 | F7: 47.375 | G7: 65.45 | H7: 93.375 | I7: 201.825 | J7: No service | K7: No service | L7: No service | M7: No service | N7: No service | O7: 2-4 Days | P7: 2-5 Days | Q7: 80 | R7: 4/5* | S7: FedEx Prioirty | T7: Priority
A8: EU | B8: Ireland | C8: Anguilla | D8: 27.47 | E8: 36.125 | F8: 40.0125 | G8: 55.9875 | H8: 76.5 | I8: 178.275 | J8: No service | K8: No service | L8: No service | M8: No service | N8: No service | O8: 7 Days | P8: 12-14 Days | Q8: 80 | R8: 4/5* | S8: FedEx Prioirty | T8: Priority
A9: EU | B9: Ireland | C9: Antigua and Barbuda | D9: 27.47 | E9: 36.125 | F9: 40.0125 | G9: 55.9875 | H9: 76.5 | I9: 178.275 | J9: No service | K9: No service | L9: No service | M9: No service | N9: No service | O9: 5 Days | P9: 8 Days | Q9: 80 | R9: 4/5* | S9: FedEx Prioirty | T9: Priority
A10: EU | B10: Ireland | C10: Argentina | D10: 27.47 | E10: 36.125 | F10: 40.0125 | G10: 55.9875 | H10: 76.5 | I10: 178.275 | J10: No service | K10: No service | L10: No service | M10: No service | N10: No service | O10: 5 Days | P10: 8 Days | Q10: 80 | R10: 4/5* | S10: FedEx Prioirty | T10: Priority
A11: EU | B11: Ireland | C11: Armenia | D11: 21.06 | E11: 28.075 | F11: 31.6625 | G11: 45.05 | H11: 70.35 | I11: 133.225 | J11: No service | K11: No service | L11: No service | M11: No service | N11: No service | O11: 3 Days | P11: 3-4 Days | Q11: 80 | R11: 4/5* | S11: FedEx Prioirty | T11: Priority
A12: EU | B12: Ireland | C12: Aruba (Netherlands) | D12: 27.47 | E12: 36.125 | F12: 40.0125 | G12: 55.9875 | H12: 76.5 | I12: 178.275 | J12: No service | K12: No service | L12: No service | M12: No service | N12: No service | O12: 5 Days | P12: 8 Days | Q12: 80 | R12: 4/5* | S12: FedEx Prioirty | T12: Priority
A13: EU | B13: Ireland | C13: Australia | D13: 47.67 | E13: 63.75 | F13: 72.325 | G13: 107.775 | H13: 153.15 | I13: 235 | J13: No service | K13: No service | L13: No service | M13: No service | N13: No service | O13: 5 Days | P13: 8 Days | Q13: 80 | R13: 4/5* | S13: FedEx Prioirty | T13: Priority
A14: EU | B14: Ireland | C14: Austria | D14: 23 | E14: 24.625 | F14: 25 | G14: 26.25 | H14: 30.625 | I14: 37.5 | J14: 47.5 | K14: 52.5 | L14: 52.5 | M14: 84.375 | N14: 86.25 | O14: 3 Days | P14: 8 Days | Q14: 80 | R14: 4/5* | S14: FedEx Prioirty | T14: Priority
A15: EU | B15: Ireland | C15: Azerbaijan | D15: 21.06 | E15: 28.075 | F15: 31.6625 | G15: 45.05 | H15: 70.35 | I15: 133.225 | J15: No service | K15: No service | L15: No service | M15: No service | N15: No service | O15: 3 Days | P15: 3-4 Days | Q15: 80 | R15: 4/5* | S15: FedEx Prioirty | T15: Priority
A16: EU | B16: Ireland | C16: Bahamas | D16: 27.47 | E16: 36.125 | F16: 40.0125 | G16: 55.9875 | H16: 76.5 | I16: 178.275 | J16: No service | K16: No service | L16: No service | M16: No service | N16: No service | O16: 5 Days | P16: 8 Days | Q16: 80 | R16: 4/5* | S16: FedEx Prioirty | T16: Priority
A17: EU | B17: Ireland | C17: Bahrain | D17: 21.06 | E17: 28.075 | F17: 31.6625 | G17: 45.05 | H17: 70.35 | I17: 133.225 | J17: No service | K17: No service | L17: No service | M17: No service | N17: No service | O17: 3 Days | P17: 3-4 Days | Q17: 80 | R17: 4/5* | S17: FedEx Prioirty | T17: Priority
A18: EU | B18: Ireland | C18: Bangladesh | D18: 21.06 | E18: 28.075 | F18: 31.6625 | G18: 45.05 | H18: 70.35 | I18: 133.225 | J18: No service | K18: No service | L18: No service | M18: No service | N18: No service | O18: 3 Days | P18: 3-4 Days | Q18: 80 | R18: 4/5* | S18: FedEx Prioirty | T18: Priority
A19: EU | B19: Ireland | C19: Barbados | D19: 27.47 | E19: 36.125 | F19: 40.0125 | G19: 55.9875 | H19: 76.5 | I19: 178.275 | J19: No service | K19: No service | L19: No service | M19: No service | N19: No service | O19: 5 Days | P19: 8 Days | Q19: 80 | R19: 4/5* | S19: FedEx Prioirty | T19: Priority
A20: EU | B20: Ireland | C20: Belarus | D20: No service | E20: No service | F20: No service | G20: No service | H20: No service | I20: No service | J20: No service | K20: No service | L20: No service | M20: No service | N20: No service | S20: FedEx Prioirty | T20: Priority
A21: EU | B21: Ireland | C21: Belgium | D21: 21.5 | E21: 23.875 | F21: 26.25 | G21: 28.75 | H21: 31.25 | I21: 36.25 | J21: 45 | K21: 51.25 | L21: 78.75 | M21: 86.25 | N21: 91.25 | O21: 3 Days | P21: 5 Days | Q21: 80 | R21: 4/5* | S21: FedEx Prioirty | T21: Priority
A22: EU | B22: Ireland | C22: Belize | D22: 27.47 | E22: 36.125 | F22: 40.0125 | G22: 55.9875 | H22: 76.5 | I22: 178.275 | J22: No service | K22: No service | L22: No service | M22: No service | N22: No service | O22: 5 Days | P22: 8 Days | Q22: 80 | R22: 4/5* | S22: FedEx Prioirty | T22: Priority
A23: EU | B23: Ireland | C23: Benin | D23: 34.52 | E23: 42.1875 | F23: 47.375 | G23: 65.45 | H23: 93.375 | I23: 201.825 | J23: No service | K23: No service | L23: No service | M23: No service | N23: No service | O23: 5 Days | P23: 9 Days | Q23: 80 | R23: 4/5* | S23: FedEx Prioirty | T23: Priority
A24: EU | B24: Ireland | C24: Bermuda (BOT) | D24: 27.47 | E24: 36.125 | F24: 40.0125 | G24: 55.9875 | H24: 76.5 | I24: 178.275 | J24: No service | K24: No service | L24: No service | M24: No service | N24: No service | O24: 5 Days | P24: 8 Days | Q24: 80 | R24: 4/5* | S24: FedEx Prioirty | T24: Priority
A25: EU | B25: Ireland | C25: Bhutan | D25: 21.06 | E25: 28.075 | F25: 31.6625 | G25: 45.05 | H25: 70.35 | I25: 133.225 | J25: No service | K25: No service | L25: No service | M25: No service | N25: No service | O25: 3 Days | P25: 3-4 Days | Q25: 80 | R25: 4/5* | S25: FedEx Prioirty | T25: Priority
A26: EU | B26: Ireland | C26: Bolivia | D26: 30.11 | E26: 36.125 | F26: 40.0125 | G26: 55.9875 | H26: 76.5 | I26: 178.275 | J26: No service | K26: No service | L26: No service | M26: No service | N26: No service | O26: 8 Days | P26: 9 Days | Q26: 80 | R26: 4/5* | S26: FedEx Prioirty | T26: Priority
A27: EU | B27: Ireland | C27: Bonaire | D27: 30.11 | E27: 36.125 | F27: 40.0125 | G27: 55.9875 | H27: 76.5 | I27: 178.275 | J27: No service | K27: No service | L27: No service | M27: No service | N27: No service | O27: 8 Days | P27: 9 Days | Q27: 80 | R27: 4/5* | S27: FedEx Prioirty | T27: Priority
A28: EU | B28: Ireland | C28: Bosnia and Herzegovina | D28: 35.5 | E28: 44.375 | F28: 47.375 | G28: 56.875 | H28: 61.25 | I28: 68.75 | J28: No service | K28: No service | L28: No service | M28: No service | N28: No service | O28: 3 Days | P28: 4 Days | Q28: 80 | R28: 4/5* | S28: FedEx Prioirty | T28: Priority
A29: EU | B29: Ireland | C29: Botswana | D29: 31.72 | E29: 42.1875 | F29: 47.375 | G29: 65.45 | H29: 93.375 | I29: 201.825 | J29: No service | K29: No service | L29: No service | M29: No service | N29: No service | O29: 2-4 Days | P29: 2-5 Days | Q29: 80 | R29: 4/5* | S29: FedEx Prioirty | T29: Priority
A30: EU | B30: Ireland | C30: Brazil | D30: 27.47 | E30: 36.125 | F30: 40.0125 | G30: 55.9875 | H30: 76.5 | I30: 178.275 | J30: No service | K30: No service | L30: No service | M30: No service | N30: No service | O30: 5 Days | P30: 8 Days | Q30: 80 | R30: 4/5* | S30: FedEx Prioirty | T30: Priority
A31: EU | B31: Ireland | C31: British Virgin Islands | D31: 30.11 | E31: 36.125 | F31: 40.0125 | G31: 55.9875 | H31: 76.5 | I31: 178.275 | J31: No service | K31: No service | L31: No service | M31: No service | N31: No service | O31: 8 Days | P31: 9 Days | Q31: 80 | R31: 4/5* | S31: FedEx Prioirty | T31: Priority
A32: EU | B32: Ireland | C32: Brunei | D32: 21.06 | E32: 28.075 | F32: 31.6625 | G32: 45.05 | H32: 70.35 | I32: 133.225 | J32: No service | K32: No service | L32: No service | M32: No service | N32: No service | O32: 3 Days | P32: 3-4 Days | Q32: 80 | R32: 4/5* | S32: FedEx Prioirty | T32: Priority
A33: EU | B33: Ireland | C33: Bulgaria | D33: 28 | E33: 33.75 | F33: 36.25 | G33: 38.75 | H33: 41.25 | I33: 55 | J33: 62.5 | K33: 71.25 | L33: 98.75 | M33: 106.25 | N33: 111.25 | O33: 4 Days | P33: 12 Days | Q33: 80 | R33: 4/5* | S33: FedEx Prioirty | T33: Priority
A34: EU | B34: Ireland | C34: Burkina Faso | D34: 32 | E34: 42.1875 | F34: 47.375 | G34: 65.45 | H34: 93.375 | I34: 201.825 | J34: No service | K34: No service | L34: No service | M34: No service | N34: No service | O34: 9 Days | P34: 10-12 Days | Q34: 80 | R34: 4/5* | S34: FedEx Prioirty | T34: Priority
A35: EU | B35: Ireland | C35: Burundi | D35: 32 | E35: 42.1875 | F35: 47.375 | G35: 65.45 | H35: 93.375 | I35: 201.825 | J35: No service | K35: No service | L35: No service | M35: No service | N35: No service | O35: 9 Days | P35: 10-12 Days | Q35: 80 | R35: 4/5* | S35: FedEx Prioirty | T35: Priority
A36: EU | B36: Ireland | C36: Cambodia | D36: 25.05 | E36: 33.05 | F36: 37.5875 | G36: 54.8375 | H36: 77.575 | I36: 137.9125 | J36: No service | K36: No service | L36: No service | M36: No service | N36: No service | O36: 7 Days | P36: 10-13 Days | Q36: 80 | R36: 4/5* | S36: FedEx Prioirty | T36: Priority
A37: EU | B37: Ireland | C37: Cameroon | D37: 31.72 | E37: 42.1875 | F37: 47.375 | G37: 65.45 | H37: 93.375 | I37: 201.825 | J37: No service | K37: No service | L37: No service | M37: No service | N37: No service | O37: 2-4 Days | P37: 2-5 Days | Q37: 80 | R37: 4/5* | S37: FedEx Prioirty | T37: Priority
A38: EU | B38: Ireland | C38: Canada | D38: 29.45 | E38: 29.8125 | F38: 33.875 | G38: 51.15 | H38: 71.325 | I38: 139.8875 | J38: No service | K38: No service | L38: No service | M38: No service | N38: No service | O38: 2-4 Days | P38: 6-7 Days | Q38: 80 | R38: 4/5* | S38: FedEx Prioirty | T38: Priority
A39: EU | B39: Ireland | C39: Cape Verde | D39: 31.72 | E39: 42.1875 | F39: 47.375 | G39: 65.45 | H39: 93.375 | I39: 201.825 | J39: No service | K39: No service | L39: No service | M39: No service | N39: No service | O39: 2-4 Days | P39: 2-5 Days | Q39: 80 | R39: 4/5* | S39: FedEx Prioirty | T39: Priority
A40: EU | B40: Ireland | C40: Cayman Islands | D40: 27.47 | E40: 36.125 | F40: 40.0125 | G40: 55.9875 | H40: 76.5 | I40: 178.275 | J40: No service | K40: No service | L40: No service | M40: No service | N40: No service | O40: 5 Days | P40: 8 Days | Q40: 80 | R40: 4/5* | S40: FedEx Prioirty | T40: Priority
...

Sheet Result
A1: Type | B1: Ship From | C1: Ship To | D1: Doc 0.5kg | E1: Paket 1kg | F1: Paket 2kg | G1: Box 5kg | H1: Box 10kg | I1: Box 15kg | J1: Box 20kg | K1: Box 25kg | L1: Suitcase 10kg | M1: Suitcase 20kg | N1: Suitcase 30kg | O1: Days ENV | P1: Days PARCEL | Q1: Insurance | R1: Rating | S1: Courier | T1: Service
A3: =IF('Rates from Ireland Fedex Priort'!A2="","",'Rates from Ireland Fedex Priort'!A2) -> EU | B3: =IF('Rates from Ireland Fedex Priort'!B2="","",'Rates from Ireland Fedex Priort'!B2) -> Ireland | C3: =IF('Rates from Ireland Fedex Priort'!C2="","",'Rates from Ireland Fedex Priort'!C2) -> Afghanistan | D3: =IF(ISNUMBER('Rates from Ireland Fedex Priort'!D2),_xlfn.CEILING.MATH('Rates from Ireland Fedex Priort'!D2,1)+(IF($A3="EU",Variables!$B$5,IF($A3="N/A",0,Variables!$B$2))),'Rates from Ireland Fedex Priort'!D2) -> No service | E3: =IF(ISNUMBER('Rates from Ireland Fedex Priort'!E2),_xlfn.CEILING.MATH('Rates from Ireland Fedex Priort'!E2,1)+IF($A3="EU",Variables!$B$6,Variables!$B$3),'Rates from Ireland Fedex Priort'!E2) -> No service | F3: =IF(ISNUMBER('Rates from Ireland Fedex Priort'!F2),_xlfn.CEILING.MATH('Rates from Ireland Fedex Priort'!F2,1)+IF($A3="EU",Variables!$B$6,Variables!$B$3),'Rates from Ireland Fedex Priort'!F2) -> No service | G3: =IF(ISNUMBER('Rates from Ireland Fedex Priort'!G2),_xlfn.CEILING.MATH('Rates from Ireland Fedex Priort'!G2,1)+IF($A3="EU",Variables!$B$6,Variables!$B$3),'Rates from Ireland Fedex Priort'!G2) -> No service | H3: =IF(ISNUMBER('Rates from Ireland Fedex Priort'!H2),_xlfn.CEILING.MATH('Rates from Ireland Fedex Priort'!H2,1)+IF($A3="EU",Variables!$B$6,Variables!$B$3),'Rates from Ireland Fedex Priort'!H2) -> No service | I3: =IF(ISNUMBER('Rates from Ireland Fedex Priort'!I2),_xlfn.CEILING.MATH('Rates from Ireland Fedex Priort'!I2,1)+IF($A3="EU",Variables!$B$6,Variables!$B$3),'Rates from Ireland Fedex Priort'!I2) -> No service | J3: =IF(ISNUMBER('Rates from Ireland Fedex Priort'!J2),_xlfn.CEILING.MATH('Rates from Ireland Fedex Priort'!J2,1)+IF($A3="EU",Variables!$B$6,Variables!$B$3),'Rates from Ireland Fedex Priort'!J2) -> No service | K3: =IF(ISNUMBER('Rates from Ireland Fedex Priort'!K2),_xlfn.CEILING.MATH('Rates from Ireland Fedex Priort'!K2,1)+IF($A3="EU",Variables!$B$6,Variables!$B$3),'Rates from Ireland Fedex Priort'!K2) -> No service | L3: =IF(ISNUMBER('Rates from Ireland Fedex Priort'!L2),_xlfn.CEILING.MATH('Rates from Ireland Fedex Priort'!L2,1)+IF($A3="EU",Variables!$B$6,Variables!$B$3),'Rates from Ireland Fedex Priort'!L2) -> No service | ... N3: =IF(ISNUMBER('Rates from Ireland Fedex Priort'!N2),_xlfn.CEILING.MATH('Rates from Ireland Fedex Priort'!N2,1)+IF($A3="EU",Variables!$B$6,Variables!$B$3),'Rates from Ireland Fedex Priort'!N2) -> No service
A4: =IF('Rates from Ireland Fedex Priort'!A3="","",'Rates from Ireland Fedex Priort'!A3) -> EU | B4: =IF('Rates from Ireland Fedex Priort'!B3="","",'Rates from Ireland Fedex Priort'!B3) -> Ireland | C4: =IF('Rates from Ireland Fedex Priort'!C3="","",'Rates from Ireland Fedex Priort'!C3) -> Albania | D4: =IF(ISNUMBER('Rates from Ireland Fedex Priort'!D3),_xlfn.CEILING.MATH('Rates from Ireland Fedex Priort'!D3,1)+(IF($A4="EU",Variables!$B$5,IF($A4="N/A",0,Variables!$B$2))),'Rates from Ireland Fedex Priort'!D3) -> 76 | E4: =IF(ISNUMBER('Rates from Ireland Fedex Priort'!E3),_xlfn.CEILING.MATH('Rates from Ireland Fedex Priort'!E3,1)+IF($A4="EU",Variables!$B$6,Variables!$B$3),'Rates from Ireland Fedex Priort'!E3) -> 85 | F4: =IF(ISNUMBER('Rates from Ireland Fedex Priort'!F3),_xlfn.CEILING.MATH('Rates from Ireland Fedex Priort'!F3,1)+IF($A4="EU",Variables!$B$6,Variables!$B$3),'Rates from Ireland Fedex Priort'!F3) -> 88 | G4: =IF(ISNUMBER('Rates from Ireland Fedex Priort'!G3),_xlfn.CEILING.MATH('Rates from Ireland Fedex Priort'!G3,1)+IF($A4="EU",Variables!$B$6,Variables!$B$3),'Rates from Ireland Fedex Priort'!G3) -> 97 | H4: =IF(ISNUMBER('Rates from Ireland Fedex Priort'!H3),_xlfn.CEILING.MATH('Rates from Ireland Fedex Priort'!H3,1)+IF($A4="EU",Variables!$B$6,Variables!$B$3),'Rates from Ireland Fedex Priort'!H3) -> 102 | I4: =IF(ISNUMBER('Rates from Ireland Fedex Priort'!I3),_xlfn.CEILING.MATH('Rates from Ireland Fedex Priort'!I3,1)+IF($A4="EU",Variables!$B$6,Variables!$B$3),'Rates from Ireland Fedex Priort'!I3) -> 109 | J4: =IF(ISNUMBER('Rates from Ireland Fedex Priort'!J3),_xlfn.CEILING.MATH('Rates from Ireland Fedex Priort'!J3,1)+IF($A4="EU",Variables!$B$6,Variables!$B$3),'Rates from Ireland Fedex Priort'!J3) -> No service | K4: =IF(ISNUMBER('Rates from Ireland Fedex Priort'!K3),_xlfn.CEILING.MATH('Rates from Ireland Fedex Priort'!K3,1)+IF($A4="EU",Variables!$B$6,Variables!$B$3),'Rates from Ireland Fedex Priort'!K3) -> No service | L4: =IF(ISNUMBER('Rates from Ireland Fedex Priort'!L3),_xlfn.CEILING.MATH('Rates from Ireland Fedex Priort'!L3,1)+IF($A4="EU",Variables!$B$6,Variables!$B$3),'Rates from Ireland Fedex Priort'!L3) -> No service | ... N4: =IF(ISNUMBER('Rates from Ireland Fedex Priort'!N3),_xlfn.CEILING.MATH('Rates from Ireland Fedex Priort'!N3,1)+IF($A4="EU",Variables!$B$6,Variables!$B$3),'Rates from Ireland Fedex Priort'!N3) -> No service | O4: 8 Days | P4: 9 Days | Q4: 80 | R4: 4/5* | S4: FedEx Economy | T4: Economy
A5: =IF('Rates from Ireland Fedex Priort'!A4="","",'Rates from Ireland Fedex Priort'!A4) -> EU | B5: =IF('Rates from Ireland Fedex Priort'!B4="","",'Rates from Ireland Fedex Priort'!B4) -> Ireland | C5: =IF('Rates from Ireland Fedex Priort'!C4="","",'Rates from Ireland Fedex Priort'!C4) -> Algeria | D5: =IF(ISNUMBER('Rates from Ireland Fedex Priort'!D4),_xlfn.CEILING.MATH('Rates from Ireland Fedex Priort'!D4,1)+(IF($A5="EU",Variables!$B$5,IF($A5="N/A",0,Variables!$B$2))),'Rates from Ireland Fedex Priort'!D4) -> 62 | E5: =IF(ISNUMBER('Rates from Ireland Fedex Priort'!E4),_xlfn.CEILING.MATH('Rates from Ireland Fedex Priort'!E4,1)+IF($A5="EU",Variables!$B$6,Variables!$B$3),'Rates from Ireland Fedex Priort'!E4) -> 69 | F5: =IF(ISNUMBER('Rates from Ireland Fedex Priort'!F4),_xlfn.CEILING.MATH('Rates from Ireland Fedex Priort'!F4,1)+IF($A5="EU",Variables!$B$6,Variables!$B$3),'Rates from Ireland Fedex Priort'!F4) -> 72 | G5: =IF(ISNUMBER('Rates from Ireland Fedex Priort'!G4),_xlfn.CEILING.MATH('Rates from Ireland Fedex Priort'!G4,1)+IF($A5="EU",Variables!$B$6,Variables!$B$3),'Rates from Ireland Fedex Priort'!G4) -> 86 | H5: =IF(ISNUMBER('Rates from Ireland Fedex Priort'!H4),_xlfn.CEILING.MATH('Rates from Ireland Fedex Priort'!H4,1)+IF($A5="EU",Variables!$B$6,Variables!$B$3),'Rates from Ireland Fedex Priort'!H4) -> 111 | I5: =IF(ISNUMBER('Rates from Ireland Fedex Priort'!I4),_xlfn.CEILING.MATH('Rates from Ireland Fedex Priort'!I4,1)+IF($A5="EU",Variables!$B$6,Variables!$B$3),'Rates from Ireland Fedex Priort'!I4) -> 174 | J5: =IF(ISNUMBER('Rates from Ireland Fedex Priort'!J4),_xlfn.CEILING.MATH('Rates from Ireland Fedex Priort'!J4,1)+IF($A5="EU",Variables!$B$6,Variables!$B$3),'Rates from Ireland Fedex Priort'!J4) -> No service | K5: =IF(ISNUMBER('Rates from Ireland Fedex Priort'!K4),_xlfn.CEILING.MATH('Rates from Ireland Fedex Priort'!K4,1)+IF($A5="EU",Variables!$B$6,Variables!$B$3),'Rates from Ireland Fedex Priort'!K4) -> No service | L5: =IF(ISNUMBER('Rates from Ireland Fedex Priort'!L4),_xlfn.CEILING.MATH('Rates from Ireland Fedex Priort'!L4,1)+IF($A5="EU",Variables!$B$6,Variables!$B$3),'Rates from Ireland Fedex Priort'!L4) -> No service | ... N5: =IF(ISNUMBER('Rates from Ireland Fedex Priort'!N4),_xlfn.CEILING.MATH('Rates from Ireland Fedex Priort'!N4,1)+IF($A5="EU",Variables!$B$6,Variables!$B$3),'Rates from Ireland Fedex Priort'!N4) -> No service | O5: 3 Days | P5: 3-4 Days | Q5: 80 | R5: 4/5* | S5: FedEx Economy | T5: Economy
A6: =IF('Rates from Ireland Fedex Priort'!A5="","",'Rates from Ireland Fedex Priort'!A5) -> EU | B6: =IF('Rates from Ireland Fedex Priort'!B5="","",'Rates from Ireland Fedex Priort'!B5) -> Ireland | C6: =IF('Rates from Ireland Fedex Priort'!C5="","",'Rates from Ireland Fedex Priort'!C5) -> American Samoa (US) | D6: =IF(ISNUMBER('Rates from Ireland Fedex Priort'!D5),_xlfn.CEILING.MATH('Rates from Ireland Fedex Priort'!D5,1)+IF($A6="EU",Variables!$B$5,Variables!$B$2),'Rates from Ireland Fedex Priort'!D5) -> 72 | E6: =IF(ISNUMBER('Rates from Ireland Fedex Priort'!E5),_xlfn.CEILING.MATH('Rates from Ireland Fedex Priort'!E5,1)+IF($A6="EU",Variables!$B$6,Variables!$B$3),'Rates from Ireland Fedex Priort'!E5) -> 83 | F6: =IF(ISNUMBER('Rates from Ireland Fedex Priort'!F5),_xlfn.CEILING.MATH('Rates from Ireland Fedex Priort'!F5,1)+IF($A6="EU",Variables!$B$6,Variables!$B$3),'Rates from Ireland Fedex Priort'!F5) -> 88 | G6: =IF(ISNUMBER('Rates from Ireland Fedex Priort'!G5),_xlfn.CEILING.MATH('Rates from Ireland Fedex Priort'!G5,1)+IF($A6="EU",Variables!$B$6,Variables!$B$3),'Rates from Ireland Fedex Priort'!G5) -> 106 | H6: =IF(ISNUMBER('Rates from Ireland Fedex Priort'!H5),_xlfn.CEILING.MATH('Rates from Ireland Fedex Priort'!H5,1)+IF($A6="EU",Variables!$B$6,Variables!$B$3),'Rates from Ireland Fedex Priort'!H5) -> No service | I6: =IF(ISNUMBER('Rates from Ireland Fedex Priort'!I5),_xlfn.CEILING.MATH('Rates from Ireland Fedex Priort'!I5,1)+IF($A6="EU",Variables!$B$6,Variables!$B$3),'Rates from Ireland Fedex Priort'!I5) -> No service | J6: =IF(ISNUMBER('Rates from Ireland Fedex Priort'!J5),_xlfn.CEILING.MATH('Rates from Ireland Fedex Priort'!J5,1)+IF($A6="EU",Variables!$B$6,Variables!$B$3),'Rates from Ireland Fedex Priort'!J5) -> No service | K6: =IF(ISNUMBER('Rates from Ireland Fedex Priort'!K5),_xlfn.CEILING.MATH('Rates from Ireland Fedex Priort'!K5,1)+IF($A6="EU",Variables!$B$6,Variables!$B$3),'Rates from Ireland Fedex Priort'!K5) -> No service | L6: =IF(ISNUMBER('Rates from Ireland Fedex Priort'!L5),_xlfn.CEILING.MATH('Rates from Ireland Fedex Priort'!L5,1)+IF($A6="EU",Variables!$B$6,Variables!$B$3),'Rates from Ireland Fedex Priort'!L5) -> No service | ... N6: =IF(ISNUMBER('Rates from Ireland Fedex Priort'!N5),_xlfn.CEILING.MATH('Rates from Ireland Fedex Priort'!N5,1)+IF($A6="EU",Variables!$B$6,Variables!$B$3),'Rates from Ireland Fedex Priort'!N5) -> No service | S6: FedEx Economy | T6: Economy
A7: =IF('Rates from Ireland Fedex Priort'!A6="","",'Rates from Ireland Fedex Priort'!A6) -> EU | B7: =IF('Rates from Ireland Fedex Priort'!B6="","",'Rates from Ireland Fedex Priort'!B6) -> Ireland | C7: =IF('Rates from Ireland Fedex Priort'!C6="","",'Rates from Ireland Fedex Priort'!C6) -> Andorra | D7: =IF(ISNUMBER('Rates from Ireland Fedex Priort'!D6),_xlfn.CEILING.MATH('Rates from Ireland Fedex Priort'!D6,1)+IF($A7="EU",Variables!$B$5,Variables!$B$2),'Rates from Ireland Fedex Priort'!D6) -> 63 | E7: =IF(ISNUMBER('Rates from Ireland Fedex Priort'!E6),_xlfn.CEILING.MATH('Rates from Ireland Fedex Priort'!E6,1)+IF($A7="EU",Variables!$B$6,Variables!$B$3),'Rates from Ireland Fedex Priort'!E6) -> 65 | F7: =IF(ISNUMBER('Rates from Ireland Fedex Priort'!F6),_xlfn.CEILING.MATH('Rates from Ireland Fedex Priort'!F6,1)+IF($A7="EU",Variables!$B$6,Variables!$B$3),'Rates from Ireland Fedex Priort'!F6) -> 65 | G7: =IF(ISNUMBER('Rates from Ireland Fedex Priort'!G6),_xlfn.CEILING.MATH('Rates from Ireland Fedex Priort'!G6,1)+IF($A7="EU",Variables!$B$6,Variables!$B$3),'Rates from Ireland Fedex Priort'!G6) -> 67 | H7: =IF(ISNUMBER('Rates from Ireland Fedex Priort'!H6),_xlfn.CEILING.MATH('Rates from Ireland Fedex Priort'!H6,1)+IF($A7="EU",Variables!$B$6,Variables!$B$3),'Rates from Ireland Fedex Priort'!H6) -> 71 | I7: =IF(ISNUMBER('Rates from Ireland Fedex Priort'!I6),_xlfn.CEILING.MATH('Rates from Ireland Fedex Priort'!I6,1)+IF($A7="EU",Variables!$B$6,Variables!$B$3),'Rates from Ireland Fedex Priort'!I6) -> 78 | J7: =IF(ISNUMBER('Rates from Ireland Fedex Priort'!J6),_xlfn.CEILING.MATH('Rates from Ireland Fedex Priort'!J6,1)+IF($A7="EU",Variables!$B$6,Variables!$B$3),'Rates from Ireland Fedex Priort'!J6) -> No service | K7: =IF(ISNUMBER('Rates from Ireland Fedex Priort'!K6),_xlfn.CEILING.MATH('Rates from Ireland Fedex Priort'!K6,1)+IF($A7="EU",Variables!$B$6,Variables!$B$3),'Rates from Ireland Fedex Priort'!K6) -> No service | L7: =IF(ISNUMBER('Rates from Ireland Fedex Priort'!L6),_xlfn.CEILING.MATH('Rates from Ireland Fedex Priort'!L6,1)+IF($A7="EU",Variables!$B$6,Variables!$B$3),'Rates from Ireland Fedex Priort'!L6) -> No service | ... N7: =IF(ISNUMBER('Rates from Ireland Fedex Priort'!N6),_xlfn.CEILING.MATH('Rates from Ireland Fedex Priort'!N6,1)+IF($A7="EU",Variables!$B$6,Variables!$B$3),'Rates from Ireland Fedex Priort'!N6) -> No service | O7: 6 Days | P7: 8 Days | Q7: 80 | R7: 4/5* | S7: FedEx Economy | T7: Economy
A8: =IF('Rates from Ireland Fedex Priort'!A7="","",'Rates from Ireland Fedex Priort'!A7) -> EU | B8: =IF('Rates from Ireland Fedex Priort'!B7="","",'Rates from Ireland Fedex Priort'!B7) -> Ireland | C8: =IF('Rates from Ireland Fedex Priort'!C7="","",'Rates from Ireland Fedex Priort'!C7) -> Angola | D8: =IF(ISNUMBER('Rates from Ireland Fedex Priort'!D7),_xlfn.CEILING.MATH('Rates from Ireland Fedex Priort'!D7,1)+IF($A8="EU",Variables!$B$5,Variables!$B$2),'Rates from Ireland Fedex Priort'!D7) -> 72 | E8: =IF(ISNUMBER('Rates from Ireland Fedex Priort'!E7),_xlfn.CEILING.MATH('Rates from Ireland Fedex Priort'!E7,1)+IF($A8="EU",Variables!$B$6,Variables!$B$3),'Rates from Ireland Fedex Priort'!E7) -> 83 | F8: =IF(ISNUMBER('Rates from Ireland Fedex Priort'!F7),_xlfn.CEILING.MATH('Rates from Ireland Fedex Priort'!F7,1)+IF($A8="EU",Variables!$B$6,Variables!$B$3),'Rates from Ireland Fedex Priort'!F7) -> 88 | G8: =IF(ISNUMBER('Rates from Ireland Fedex Priort'!G7),_xlfn.CEILING.MATH('Rates from Ireland Fedex Priort'!G7,1)+IF($A8="EU",Variables!$B$6,Variables!$B$3),'Rates from Ireland Fedex Priort'!G7) -> 106 | H8: =IF(ISNUMBER('Rates from Ireland Fedex Priort'!H7),_xlfn.CEILING.MATH('Rates from Ireland Fedex Priort'!H7,1)+IF($A8="EU",Variables!$B$6,Variables!$B$3),'Rates from Ireland Fedex Priort'!H7) -> 134 | I8: =IF(ISNUMBER('Rates from Ireland Fedex Priort'!I7),_xlfn.CEILING.MATH('Rates from Ireland Fedex Priort'!I7,1)+IF($A8="EU",Variables!$B$6,Variables!$B$3),'Rates from Ireland Fedex Priort'!I7) -> 242 | J8: =IF(ISNUMBER('Rates from Ireland Fedex Priort'!J7),_xlfn.CEILING.MATH('Rates from Ireland Fedex Priort'!J7,1)+IF($A8="EU",Variables!$B$6,Variables!$B$3),'Rates from Ireland Fedex Priort'!J7) -> No service | K8: =IF(ISNUMBER('Rates from Ireland Fedex Priort'!K7),_xlfn.CEILING.MATH('Rates from Ireland Fedex Priort'!K7,1)+IF($A8="EU",Variables!$B$6,Variables!$B$3),'Rates from Ireland Fedex Priort'!K7) -> No service | L8: =IF(ISNUMBER('Rates from Ireland Fedex Priort'!L7),_xlfn.CEILING.MATH('Rates from Ireland Fedex Priort'!L7,1)+IF($A8="EU",Variables!$B$6,Variables!$B$3),'Rates from Ireland Fedex Priort'!L7) -> No service | ... N8: =IF(ISNUMBER('Rates from Ireland Fedex Priort'!N7),_xlfn.CEILING.MATH('Rates from Ireland Fedex Priort'!N7,1)+IF($A8="EU",Variables!$B$6,Variables!$B$3),'Rates from Ireland Fedex Priort'!N7) -> No service | O8: 2-4 Days | P8: 2-5 Days | Q8: 80 | R8: 4/5* | S8: FedEx Economy | T8: Economy
A9: =IF('Rates from Ireland Fedex Priort'!A8="","",'Rates from Ireland Fedex Priort'!A8) -> EU | B9: =IF('Rates from Ireland Fedex Priort'!B8="","",'Rates from Ireland Fedex Priort'!B8) -> Ireland | C9: =IF('Rates from Ireland Fedex Priort'!C8="","",'Rates from Ireland Fedex Priort'!C8) -> Anguilla | D9: =IF(ISNUMBER('Rates from Ireland Fedex Priort'!D8),_xlfn.CEILING.MATH('Rates from Ireland Fedex Priort'!D8,1)+IF($A9="EU",Variables!$B$5,Variables!$B$2),'Rates from Ireland Fedex Priort'!D8) -> 68 | E9: =IF(ISNUMBER('Rates from Ireland Fedex Priort'!E8),_xlfn.CEILING.MATH('Rates from Ireland Fedex Priort'!E8,1)+IF($A9="EU",Variables!$B$6,Variables!$B$3),'Rates from Ireland Fedex Priort'!E8) -> 77 | F9: =IF(ISNUMBER('Rates from Ireland Fedex Priort'!F8),_xlfn.CEILING.MATH('Rates from Ireland Fedex Priort'!F8,1)+IF($A9="EU",Variables!$B$6,Variables!$B$3),'Rates from Ireland Fedex Priort'!F8) -> 81 | G9: =IF(ISNUMBER('Rates from Ireland Fedex Priort'!G8),_xlfn.CEILING.MATH('Rates from Ireland Fedex Priort'!G8,1)+IF($A9="EU",Variables!$B$6,Variables!$B$3),'Rates from Ireland Fedex Priort'!G8) -> 96 | H9: =IF(ISNUMBER('Rates from Ireland Fedex Priort'!H8),_xlfn.CEILING.MATH('Rates from Ireland Fedex Priort'!H8,1)+IF($A9="EU",Variables!$B$6,Variables!$B$3),'Rates from Ireland Fedex Priort'!H8) -> 117 | I9: =IF(ISNUMBER('Rates from Ireland Fedex Priort'!I8),_xlfn.CEILING.MATH('Rates from Ireland Fedex Priort'!I8,1)+IF($A9="EU",Variables!$B$6,Variables!$B$3),'Rates from Ireland Fedex Priort'!I8) -> 219 | J9: =IF(ISNUMBER('Rates from Ireland Fedex Priort'!J8),_xlfn.CEILING.MATH('Rates from Ireland Fedex Priort'!J8,1)+IF($A9="EU",Variables!$B$6,Variables!$B$3),'Rates from Ireland Fedex Priort'!J8) -> No service | K9: =IF(ISNUMBER('Rates from Ireland Fedex Priort'!K8),_xlfn.CEILING.MATH('Rates from Ireland Fedex Priort'!K8,1)+IF($A9="EU",Variables!$B$6,Variables!$B$3),'Rates from Ireland Fedex Priort'!K8) -> No service | L9: =IF(ISNUMBER('Rates from Ireland Fedex Priort'!L8),_xlfn.CEILING.MATH('Rates from Ireland Fedex Priort'!L8,1)+IF($A9="EU",Variables!$B$6,Variables!$B$3),'Rates from Ireland Fedex Priort'!L8) -> No service | ... N9: =IF(ISNUMBER('Rates from Ireland Fedex Priort'!N8),_xlfn.CEILING.MATH('Rates from Ireland Fedex Priort'!N8,1)+IF($A9="EU",Variables!$B$6,Variables!$B$3),'Rates from Ireland Fedex Priort'!N8) -> No service | O9: 7 Days | P9: 12-14 Days | Q9: 80 | R9: 4/5* | S9: FedEx Economy | T9: Economy
A10: =IF('Rates from Ireland Fedex Priort'!A9="","",'Rates from Ireland Fedex Priort'!A9) -> EU | B10: =IF('Rates from Ireland Fedex Priort'!B9="","",'Rates from Ireland Fedex Priort'!B9) -> Ireland | C10: =IF('Rates from Ireland Fedex Priort'!C9="","",'Rates from Ireland Fedex Priort'!C9) -> Antigua and Barbuda | D10: =IF(ISNUMBER('Rates from Ireland Fedex Priort'!D9),_xlfn.CEILING.MATH('Rates from Ireland Fedex Priort'!D9,1)+IF($A10="EU",Variables!$B$5,Variables!$B$2),'Rates from Ireland Fedex Priort'!D9) -> 68 | E10: =IF(ISNUMBER('Rates from Ireland Fedex Priort'!E9),_xlfn.CEILING.MATH('Rates from Ireland Fedex Priort'!E9,1)+IF($A10="EU",Variables!$B$6,Variables!$B$3),'Rates from Ireland Fedex Priort'!E9) -> 77 | F10: =IF(ISNUMBER('Rates from Ireland Fedex Priort'!F9),_xlfn.CEILING.MATH('Rates from Ireland Fedex Priort'!F9,1)+IF($A10="EU",Variables!$B$6,Variables!$B$3),'Rates from Ireland Fedex Priort'!F9) -> 81 | G10: =IF(ISNUMBER('Rates from Ireland Fedex Priort'!G9),_xlfn.CEILING.MATH('Rates from Ireland Fedex Priort'!G9,1)+IF($A10="EU",Variables!$B$6,Variables!$B$3),'Rates from Ireland Fedex Priort'!G9) -> 96 | H10: =IF(ISNUMBER('Rates from Ireland Fedex Priort'!H9),_xlfn.CEILING.MATH('Rates from Ireland Fedex Priort'!H9,1)+IF($A10="EU",Variables!$B$6,Variables!$B$3),'Rates from Ireland Fedex Priort'!H9) -> 117 | I10: =IF(ISNUMBER('Rates from Ireland Fedex Priort'!I9),_xlfn.CEILING.MATH('Rates from Ireland Fedex Priort'!I9,1)+IF($A10="EU",Variables!$B$6,Variables!$B$3),'Rates from Ireland Fedex Priort'!I9) -> 219 | J10: =IF(ISNUMBER('Rates from Ireland Fedex Priort'!J9),_xlfn.CEILING.MATH('Rates from Ireland Fedex Priort'!J9,1)+IF($A10="EU",Variables!$B$6,Variables!$B$3),'Rates from Ireland Fedex Priort'!J9) -> No service | K10: =IF(ISNUMBER('Rates from Ireland Fedex Priort'!K9),_xlfn.CEILING.MATH('Rates from Ireland Fedex Priort'!K9,1)+IF($A10="EU",Variables!$B$6,Variables!$B$3),'Rates from Ireland Fedex Priort'!K9) -> No service | L10: =IF(ISNUMBER('Rates from Ireland Fedex Priort'!L9),_xlfn.CEILING.MATH('Rates from Ireland Fedex Priort'!L9,1)+IF($A10="EU",Variables!$B$6,Variables!$B$3),'Rates from Ireland Fedex Priort'!L9) -> No service | ... N10: =IF(ISNUMBER('Rates from Ireland Fedex Priort'!N9),_xlfn.CEILING.MATH('Rates from Ireland Fedex Priort'!N9,1)+IF($A10="EU",Variables!$B$6,Variables!$B$3),'Rates from Ireland Fedex Priort'!N9) -> No service | O10: 5 Days | P10: 8 Days | Q10: 80 | R10: 4/5* | S10: FedEx Economy | T10: Economy
A11: =IF('Rates from Ireland Fedex Priort'!A10="","",'Rates from Ireland Fedex Priort'!A10) -> EU | B11: =IF('Rates from Ireland Fedex Priort'!B10="","",'Rates from Ireland Fedex Priort'!B10) -> Ireland | C11: =IF('Rates from Ireland Fedex Priort'!C10="","",'Rates from Ireland Fedex Priort'!C10) -> Argentina | D11: =IF(ISNUMBER('Rates from Ireland Fedex Priort'!D10),_xlfn.CEILING.MATH('Rates from Ireland Fedex Priort'!D10,1)+IF($A11="EU",Variables!$B$5,Variables!$B$2),'Rates from Ireland Fedex Priort'!D10) -> 68 | E11: =IF(ISNUMBER('Rates from Ireland Fedex Priort'!E10),_xlfn.CEILING.MATH('Rates from Ireland Fedex Priort'!E10,1)+IF($A11="EU",Variables!$B$6,Variables!$B$3),'Rates from Ireland Fedex Priort'!E10) -> 77 | F11: =IF(ISNUMBER('Rates from Ireland Fedex Priort'!F10),_xlfn.CEILING.MATH('Rates from Ireland Fedex Priort'!F10,1)+IF($A11="EU",Variables!$B$6,Variables!$B$3),'Rates from Ireland Fedex Priort'!F10) -> 81 | G11: =IF(ISNUMBER('Rates from Ireland Fedex Priort'!G10),_xlfn.CEILING.MATH('Rates from Ireland Fedex Priort'!G10,1)+IF($A11="EU",Variables!$B$6,Variables!$B$3),'Rates from Ireland Fedex Priort'!G10) -> 96 | H11: =IF(ISNUMBER('Rates from Ireland Fedex Priort'!H10),_xlfn.CEILING.MATH('Rates from Ireland Fedex Priort'!H10,1)+IF($A11="EU",Variables!$B$6,Variables!$B$3),'Rates from Ireland Fedex Priort'!H10) -> 117 | I11: =IF(ISNUMBER('Rates from Ireland Fedex Priort'!I10),_xlfn.CEILING.MATH('Rates from Ireland Fedex Priort'!I10,1)+IF($A11="EU",Variables!$B$6,Variables!$B$3),'Rates from Ireland Fedex Priort'!I10) -> 219 | J11: =IF(ISNUMBER('Rates from Ireland Fedex Priort'!J10),_xlfn.CEILING.MATH('Rates from Ireland Fedex Priort'!J10,1)+IF($A11="EU",Variables!$B$6,Variables!$B$3),'Rates from Ireland Fedex Priort'!J10) -> No service | K11: =IF(ISNUMBER('Rates from Ireland Fedex Priort'!K10),_xlfn.CEILING.MATH('Rates from Ireland Fedex Priort'!K10,1)+IF($A11="EU",Variables!$B$6,Variables!$B$3),'Rates from Ireland Fedex Priort'!K10) -> No service | L11: =IF(ISNUMBER('Rates from Ireland Fedex Priort'!L10),_xlfn.CEILING.MATH('Rates from Ireland Fedex Priort'!L10,1)+IF($A11="EU",Variables!$B$6,Variables!$B$3),'Rates from Ireland Fedex Priort'!L10) -> No service | ... N11: =IF(ISNUMBER('Rates from Ireland Fedex Priort'!N10),_xlfn.CEILING.MATH('Rates from Ireland Fedex Priort'!N10,1)+IF($A11="EU",Variables!$B$6,Variables!$B$3),'Rates from Ireland Fedex Priort'!N10) -> No service | O11: 5 Days | P11: 8 Days | Q11: 80 | R11: 4/5* | S11: FedEx Economy | T11: Economy
A12: =IF('Rates from Ireland Fedex Priort'!A11="","",'Rates from Ireland Fedex Priort'!A11) -> EU | B12: =IF('Rates from Ireland Fedex Priort'!B11="","",'Rates from Ireland Fedex Priort'!B11) -> Ireland | C12: =IF('Rates from Ireland Fedex Priort'!C11="","",'Rates from Ireland Fedex Priort'!C11) -> Armenia | D12: =IF(ISNUMBER('Rates from Ireland Fedex Priort'!D11),_xlfn.CEILING.MATH('Rates from Ireland Fedex Priort'!D11,1)+IF($A12="EU",Variables!$B$5,Variables!$B$2),'Rates from Ireland Fedex Priort'!D11) -> 62 | E12: =IF(ISNUMBER('Rates from Ireland Fedex Priort'!E11),_xlfn.CEILING.MATH('Rates from Ireland Fedex Priort'!E11,1)+IF($A12="EU",Variables!$B$6,Variables!$B$3),'Rates from Ireland Fedex Priort'!E11) -> 69 | F12: =IF(ISNUMBER('Rates from Ireland Fedex Priort'!F11),_xlfn.CEILING.MATH('Rates from Ireland Fedex Priort'!F11,1)+IF($A12="EU",Variables!$B$6,Variables!$B$3),'Rates from Ireland Fedex Priort'!F11) -> 72 | G12: =IF(ISNUMBER('Rates from Ireland Fedex Priort'!G11),_xlfn.CEILING.MATH('Rates from Ireland Fedex Priort'!G11,1)+IF($A12="EU",Variables!$B$6,Variables!$B$3),'Rates from Ireland Fedex Priort'!G11) -> 86 | H12: =IF(ISNUMBER('Rates from Ireland Fedex Priort'!H11),_xlfn.CEILING.MATH('Rates from Ireland Fedex Priort'!H11,1)+IF($A12="EU",Variables!$B$6,Variables!$B$3),'Rates from Ireland Fedex Priort'!H11) -> 111 | I12: =IF(ISNUMBER('Rates from Ireland Fedex Priort'!I11),_xlfn.CEILING.MATH('Rates from Ireland Fedex Priort'!I11,1)+IF($A12="EU",Variables!$B$6,Variables!$B$3),'Rates from Ireland Fedex Priort'!I11) -> 174 | J12: =IF(ISNUMBER('Rates from Ireland Fedex Priort'!J11),_xlfn.CEILING.MATH('Rates from Ireland Fedex Priort'!J11,1)+IF($A12="EU",Variables!$B$6,Variables!$B$3),'Rates from Ireland Fedex Priort'!J11) -> No service | K12: =IF(ISNUMBER('Rates from Ireland Fedex Priort'!K11),_xlfn.CEILING.MATH('Rates from Ireland Fedex Priort'!K11,1)+IF($A12="EU",Variables!$B$6,Variables!$B$3),'Rates from Ireland Fedex Priort'!K11) -> No service | L12: =IF(ISNUMBER('Rates from Ireland Fedex Priort'!L11),_xlfn.CEILING.MATH('Rates from Ireland Fedex Priort'!L11,1)+IF($A12="EU",Variables!$B$6,Variables!$B$3),'Rates from Ireland Fedex Priort'!L11) -> No service | ... N12: =IF(ISNUMBER('Rates from Ireland Fedex Priort'!N11),_xlfn.CEILING.MATH('Rates from Ireland Fedex Priort'!N11,1)+IF($A12="EU",Variables!$B$6,Variables!$B$3),'Rates from Ireland Fedex Priort'!N11) -> No service | O12: 3 Days | P12: 3-4 Days | Q12: 80 | R12: 4/5* | S12: FedEx Economy | T12: Economy
A13: =IF('Rates from Ireland Fedex Priort'!A12="","",'Rates from Ireland Fedex Priort'!A12) -> EU | B13: =IF('Rates from Ireland Fedex Priort'!B12="","",'Rates from Ireland Fedex Priort'!B12) -> Ireland | C13: =IF('Rates from Ireland Fedex Priort'!C12="","",'Rates from Ireland Fedex Priort'!C12) -> Aruba (Netherlands) | D13: =IF(ISNUMBER('Rates from Ireland Fedex Priort'!D12),_xlfn.CEILING.MATH('Rates from Ireland Fedex Priort'!D12,1)+IF($A13="EU",Variables!$B$5,Variables!$B$2),'Rates from Ireland Fedex Priort'!D12) -> 68 | E13: =IF(ISNUMBER('Rates from Ireland Fedex Priort'!E12),_xlfn.CEILING.MATH('Rates from Ireland Fedex Priort'!E12,1)+IF($A13="EU",Variables!$B$6,Variables!$B$3),'Rates from Ireland Fedex Priort'!E12) -> 77 | F13: =IF(ISNUMBER('Rates from Ireland Fedex Priort'!F12),_xlfn.CEILING.MATH('Rates from Ireland Fedex Priort'!F12,1)+IF($A13="EU",Variables!$B$6,Variables!$B$3),'Rates from Ireland Fedex Priort'!F12) -> 81 | G13: =IF(ISNUMBER('Rates from Ireland Fedex Priort'!G12),_xlfn.CEILING.MATH('Rates from Ireland Fedex Priort'!G12,1)+IF($A13="EU",Variables!$B$6,Variables!$B$3),'Rates from Ireland Fedex Priort'!G12) -> 96 | H13: =IF(ISNUMBER('Rates from Ireland Fedex Priort'!H12),_xlfn.CEILING.MATH('Rates from Ireland Fedex Priort'!H12,1)+IF($A13="EU",Variables!$B$6,Variables!$B$3),'Rates from Ireland Fedex Priort'!H12) -> 117 | I13: =IF(ISNUMBER('Rates from Ireland Fedex Priort'!I12),_xlfn.CEILING.MATH('Rates from Ireland Fedex Priort'!I12,1)+IF($A13="EU",Variables!$B$6,Variables!$B$3),'Rates from Ireland Fedex Priort'!I12) -> 219 | J13: =IF(ISNUMBER('Rates from Ireland Fedex Priort'!J12),_xlfn.CEILING.MATH('Rates from Ireland Fedex Priort'!J12,1)+IF($A13="EU",Variables!$B$6,Variables!$B$3),'Rates from Ireland Fedex Priort'!J12) -> No service | K13: =IF(ISNUMBER('Rates from Ireland Fedex Priort'!K12),_xlfn.CEILING.MATH('Rates from Ireland Fedex Priort'!K12,1)+IF($A13="EU",Variables!$B$6,Variables!$B$3),'Rates from Ireland Fedex Priort'!K12) -> No service | L13: =IF(ISNUMBER('Rates from Ireland Fedex Priort'!L12),_xlfn.CEILING.MATH('Rates from Ireland Fedex Priort'!L12,1)+IF($A13="EU",Variables!$B$6,Variables!$B$3),'Rates from Ireland Fedex Priort'!L12) -> No service | ... N13: =IF(ISNUMBER('Rates from Ireland Fedex Priort'!N12),_xlfn.CEILING.MATH('Rates from Ireland Fedex Priort'!N12,1)+IF($A13="EU",Variables!$B$6,Variables!$B$3),'Rates from Ireland Fedex Priort'!N12) -> No service | O13: 5 Days | P13: 8 Days | Q13: 80 | R13: 4/5* | S13: FedEx Economy | T13: Economy
A14: =IF('Rates from Ireland Fedex Priort'!A13="","",'Rates from Ireland Fedex Priort'!A13) -> EU | B14: =IF('Rates from Ireland Fedex Priort'!B13="","",'Rates from Ireland Fedex Priort'!B13) -> Ireland | C14: =IF('Rates from Ireland Fedex Priort'!C13="","",'Rates from Ireland Fedex Priort'!C13) -> Australia | D14: =IF(ISNUMBER('Rates from Ireland Fedex Priort'!D13),_xlfn.CEILING.MATH('Rates from Ireland Fedex Priort'!D13,1)+IF($A14="EU",Variables!$B$5,Variables!$B$2),'Rates from Ireland Fedex Priort'!D13) -> 88 | E14: =IF(ISNUMBER('Rates from Ireland Fedex Priort'!E13),_xlfn.CEILING.MATH('Rates from Ireland Fedex Priort'!E13,1)+IF($A14="EU",Variables!$B$6,Variables!$B$3),'Rates from Ireland Fedex Priort'!E13) -> 104 | F14: =IF(ISNUMBER('Rates from Ireland Fedex Priort'!F13),_xlfn.CEILING.MATH('Rates from Ireland Fedex Priort'!F13,1)+IF($A14="EU",Variables!$B$6,Variables!$B$3),'Rates from Ireland Fedex Priort'!F13) -> 113 | G14: =IF(ISNUMBER('Rates from Ireland Fedex Priort'!G13),_xlfn.CEILING.MATH('Rates from Ireland Fedex Priort'!G13,1)+IF($A14="EU",Variables!$B$6,Variables!$B$3),'Rates from Ireland Fedex Priort'!G13) -> 148 | H14: =IF(ISNUMBER('Rates from Ireland Fedex Priort'!H13),_xlfn.CEILING.MATH('Rates from Ireland Fedex Priort'!H13,1)+IF($A14="EU",Variables!$B$6,Variables!$B$3),'Rates from Ireland Fedex Priort'!H13) -> 194 | I14: =IF(ISNUMBER('Rates from Ireland Fedex Priort'!I13),_xlfn.CEILING.MATH('Rates from Ireland Fedex Priort'!I13,1)+IF($A14="EU",Variables!$B$6,Variables!$B$3),'Rates from Ireland Fedex Priort'!I13) -> 275 | J14: =IF(ISNUMBER('Rates from Ireland Fedex Priort'!J13),_xlfn.CEILING.MATH('Rates from Ireland Fedex Priort'!J13,1)+IF($A14="EU",Variables!$B$6,Variables!$B$3),'Rates from Ireland Fedex Priort'!J13) -> No service | K14: =IF(ISNUMBER('Rates from Ireland Fedex Priort'!K13),_xlfn.CEILING.MATH('Rates from Ireland Fedex Priort'!K13,1)+IF($A14="EU",Variables!$B$6,Variables!$B$3),'Rates from Ireland Fedex Priort'!K13) -> No service | L14: =IF(ISNUMBER('Rates from Ireland Fedex Priort'!L13),_xlfn.CEILING.MATH('Rates from Ireland Fedex Priort'!L13,1)+IF($A14="EU",Variables!$B$6,Variables!$B$3),'Rates from Ireland Fedex Priort'!L13) -> No service | ... N14: =IF(ISNUMBER('Rates from Ireland Fedex Priort'!N13),_xlfn.CEILING.MATH('Rates from Ireland Fedex Priort'!N13,1)+IF($A14="EU",Variables!$B$6,Variables!$B$3),'Rates from Ireland Fedex Priort'!N13) -> No service | O14: 5 Days | P14: 8 Days | Q14: 80 | R14: 4/5* | S14: FedEx Economy | T14: Economy
A15: =IF('Rates from Ireland Fedex Priort'!A14="","",'Rates from Ireland Fedex Priort'!A14) -> EU | B15: =IF('Rates from Ireland Fedex Priort'!B14="","",'Rates from Ireland Fedex Priort'!B14) -> Ireland | C15: =IF('Rates from Ireland Fedex Priort'!C14="","",'Rates from Ireland Fedex Priort'!C14) -> Austria | D15: =IF(ISNUMBER('Rates from Ireland Fedex Priort'!D14),_xlfn.CEILING.MATH('Rates from Ireland Fedex Priort'!D14,1)+IF($A15="EU",Variables!$B$5,Variables!$B$2),'Rates from Ireland Fedex Priort'!D14) -> 63 | E15: =IF(ISNUMBER('Rates from Ireland Fedex Priort'!E14),_xlfn.CEILING.MATH('Rates from Ireland Fedex Priort'!E14,1)+IF($A15="EU",Variables!$B$6,Variables!$B$3),'Rates from Ireland Fedex Priort'!E14) -> 65 | F15: =IF(ISNUMBER('Rates from Ireland Fedex Priort'!F14),_xlfn.CEILING.MATH('Rates from Ireland Fedex Priort'!F14,1)+IF($A15="EU",Variables!$B$6,Variables!$B$3),'Rates from Ireland Fedex Priort'!F14) -> 65 | G15: =IF(ISNUMBER('Rates from Ireland Fedex Priort'!G14),_xlfn.CEILING.MATH('Rates from Ireland Fedex Priort'!G14,1)+IF($A15="EU",Variables!$B$6,Variables!$B$3),'Rates from Ireland Fedex Priort'!G14) -> 67 | H15: =IF(ISNUMBER('Rates from Ireland Fedex Priort'!H14),_xlfn.CEILING.MATH('Rates from Ireland Fedex Priort'!H14,1)+IF($A15="EU",Variables!$B$6,Variables!$B$3),'Rates from Ireland Fedex Priort'!H14) -> 71 | I15: =IF(ISNUMBER('Rates from Ireland Fedex Priort'!I14),_xlfn.CEILING.MATH('Rates from Ireland Fedex Priort'!I14,1)+IF($A15="EU",Variables!$B$6,Variables!$B$3),'Rates from Ireland Fedex Priort'!I14) -> 78 | J15: =IF(ISNUMBER('Rates from Ireland Fedex Priort'!J14),_xlfn.CEILING.MATH('Rates from Ireland Fedex Priort'!J14,1)+IF($A15="EU",Variables!$B$6,Variables!$B$3),'Rates from Ireland Fedex Priort'!J14) -> 88 | K15: =IF(ISNUMBER('Rates from Ireland Fedex Priort'!K14),_xlfn.CEILING.MATH('Rates from Ireland Fedex Priort'!K14,1)+IF($A15="EU",Variables!$B$6,Variables!$B$3),'Rates from Ireland Fedex Priort'!K14) -> 93 | L15: =IF(ISNUMBER('Rates from Ireland Fedex Priort'!L14),_xlfn.CEILING.MATH('Rates from Ireland Fedex Priort'!L14,1)+IF($A15="EU",Variables!$B$6,Variables!$B$3),'Rates from Ireland Fedex Priort'!L14) -> 93 | ... N15: =IF(ISNUMBER('Rates from Ireland Fedex Priort'!N14),_xlfn.CEILING.MATH('Rates from Ireland Fedex Priort'!N14,1)+IF($A15="EU",Variables!$B$6,Variables!$B$3),'Rates from Ireland Fedex Priort'!N14) -> 127 | O15: 3 Days | P15: 8 Days | Q15: 80 | R15: 4/5* | S15: FedEx Economy | T15: Economy
A16: =IF('Rates from Ireland Fedex Priort'!A15="","",'Rates from Ireland Fedex Priort'!A15) -> EU | B16: =IF('Rates from Ireland Fedex Priort'!B15="","",'Rates from Ireland Fedex Priort'!B15) -> Ireland | C16: =IF('Rates from Ireland Fedex Priort'!C15="","",'Rates from Ireland Fedex Priort'!C15) -> Azerbaijan | D16: =IF(ISNUMBER('Rates from Ireland Fedex Priort'!D15),_xlfn.CEILING.MATH('Rates from Ireland Fedex Priort'!D15,1)+IF($A16="EU",Variables!$B$5,Variables!$B$2),'Rates from Ireland Fedex Priort'!D15) -> 62 | E16: =IF(ISNUMBER('Rates from Ireland Fedex Priort'!E15),_xlfn.CEILING.MATH('Rates from Ireland Fedex Priort'!E15,1)+IF($A16="EU",Variables!$B$6,Variables!$B$3),'Rates from Ireland Fedex Priort'!E15) -> 69 | F16: =IF(ISNUMBER('Rates from Ireland Fedex Priort'!F15),_xlfn.CEILING.MATH('Rates from Ireland Fedex Priort'!F15,1)+IF($A16="EU",Variables!$B$6,Variables!$B$3),'Rates from Ireland Fedex Priort'!F15) -> 72 | G16: =IF(ISNUMBER('Rates from Ireland Fedex Priort'!G15),_xlfn.CEILING.MATH('Rates from Ireland Fedex Priort'!G15,1)+IF($A16="EU",Variables!$B$6,Variables!$B$3),'Rates from Ireland Fedex Priort'!G15) -> 86 | H16: =IF(ISNUMBER('Rates from Ireland Fedex Priort'!H15),_xlfn.CEILING.MATH('Rates from Ireland Fedex Priort'!H15,1)+IF($A16="EU",Variables!$B$6,Variables!$B$3),'Rates from Ireland Fedex Priort'!H15) -> 111 | I16: =IF(ISNUMBER('Rates from Ireland Fedex Priort'!I15),_xlfn.CEILING.MATH('Rates from Ireland Fedex Priort'!I15,1)+IF($A16="EU",Variables!$B$6,Variables!$B$3),'Rates from Ireland Fedex Priort'!I15) -> 174 | J16: =IF(ISNUMBER('Rates from Ireland Fedex Priort'!J15),_xlfn.CEILING.MATH('Rates from Ireland Fedex Priort'!J15,1)+IF($A16="EU",Variables!$B$6,Variables!$B$3),'Rates from Ireland Fedex Priort'!J15) -> No service | K16: =IF(ISNUMBER('Rates from Ireland Fedex Priort'!K15),_xlfn.CEILING.MATH('Rates from Ireland Fedex Priort'!K15,1)+IF($A16="EU",Variables!$B$6,Variables!$B$3),'Rates from Ireland Fedex Priort'!K15) -> No service | L16: =IF(ISNUMBER('Rates from Ireland Fedex Priort'!L15),_xlfn.CEILING.MATH('Rates from Ireland Fedex Priort'!L15,1)+IF($A16="EU",Variables!$B$6,Variables!$B$3),'Rates from Ireland Fedex Priort'!L15) -> No service | ... N16: =IF(ISNUMBER('Rates from Ireland Fedex Priort'!N15),_xlfn.CEILING.MATH('Rates from Ireland Fedex Priort'!N15,1)+IF($A16="EU",Variables!$B$6,Variables!$B$3),'Rates from Ireland Fedex Priort'!N15) -> No service | O16: 3 Days | P16: 3-4 Days | Q16: 80 | R16: 4/5* | S16: FedEx Economy | T16: Economy
A17: =IF('Rates from Ireland Fedex Priort'!A16="","",'Rates from Ireland Fedex Priort'!A16) -> EU | B17: =IF('Rates from Ireland Fedex Priort'!B16="","",'Rates from Ireland Fedex Priort'!B16) -> Ireland | C17: =IF('Rates from Ireland Fedex Priort'!C16="","",'Rates from Ireland Fedex Priort'!C16) -> Bahamas | D17: =IF(ISNUMBER('Rates from Ireland Fedex Priort'!D16),_xlfn.CEILING.MATH('Rates from Ireland Fedex Priort'!D16,1)+IF($A17="EU",Variables!$B$5,Variables!$B$2),'Rates from Ireland Fedex Priort'!D16) -> 68 | E17: =IF(ISNUMBER('Rates from Ireland Fedex Priort'!E16),_xlfn.CEILING.MATH('Rates from Ireland Fedex Priort'!E16,1)+IF($A17="EU",Variables!$B$6,Variables!$B$3),'Rates from Ireland Fedex Priort'!E16) -> 77 | F17: =IF(ISNUMBER('Rates from Ireland Fedex Priort'!F16),_xlfn.CEILING.MATH('Rates from Ireland Fedex Priort'!F16,1)+IF($A17="EU",Variables!$B$6,Variables!$B$3),'Rates from Ireland Fedex Priort'!F16) -> 81 | G17: =IF(ISNUMBER('Rates from Ireland Fedex Priort'!G16),_xlfn.CEILING.MATH('Rates from Ireland Fedex Priort'!G16,1)+IF($A17="EU",Variables!$B$6,Variables!$B$3),'Rates from Ireland Fedex Priort'!G16) -> 96 | H17: =IF(ISNUMBER('Rates from Ireland Fedex Priort'!H16),_xlfn.CEILING.MATH('Rates from Ireland Fedex Priort'!H16,1)+IF($A17="EU",Variables!$B$6,Variables!$B$3),'Rates from Ireland Fedex Priort'!H16) -> 117 | I17: =IF(ISNUMBER('Rates from Ireland Fedex Priort'!I16),_xlfn.CEILING.MATH('Rates from Ireland Fedex Priort'!I16,1)+IF($A17="EU",Variables!$B$6,Variables!$B$3),'Rates from Ireland Fedex Priort'!I16) -> 219 | J17: =IF(ISNUMBER('Rates from Ireland Fedex Priort'!J16),_xlfn.CEILING.MATH('Rates from Ireland Fedex Priort'!J16,1)+IF($A17="EU",Variables!$B$6,Variables!$B$3),'Rates from Ireland Fedex Priort'!J16) -> No service | K17: =IF(ISNUMBER('Rates from Ireland Fedex Priort'!K16),_xlfn.CEILING.MATH('Rates from Ireland Fedex Priort'!K16,1)+IF($A17="EU",Variables!$B$6,Variables!$B$3),'Rates from Ireland Fedex Priort'!K16) -> No service | L17: =IF(ISNUMBER('Rates from Ireland Fedex Priort'!L16),_xlfn.CEILING.MATH('Rates from Ireland Fedex Priort'!L16,1)+IF($A17="EU",Variables!$B$6,Variables!$B$3),'Rates from Ireland Fedex Priort'!L16) -> No service | ... N17: =IF(ISNUMBER('Rates from Ireland Fedex Priort'!N16),_xlfn.CEILING.MATH('Rates from Ireland Fedex Priort'!N16,1)+IF($A17="EU",Variables!$B$6,Variables!$B$3),'Rates from Ireland Fedex Priort'!N16) -> No service | O17: 5 Days | P17: 8 Days | Q17: 80 | R17: 4/5* | S17: FedEx Economy | T17: Economy
A18: =IF('Rates from Ireland Fedex Priort'!A17="","",'Rates from Ireland Fedex Priort'!A17) -> EU | B18: =IF('Rates from Ireland Fedex Priort'!B17="","",'Rates from Ireland Fedex Priort'!B17) -> Ireland | C18: =IF('Rates from Ireland Fedex Priort'!C17="","",'Rates from Ireland Fedex Priort'!C17) -> Bahrain | D18: =IF(ISNUMBER('Rates from Ireland Fedex Priort'!D17),_xlfn.CEILING.MATH('Rates from Ireland Fedex Priort'!D17,1)+IF($A18="EU",Variables!$B$5,Variables!$B$2),'Rates from Ireland Fedex Priort'!D17) -> 62 | E18: =IF(ISNUMBER('Rates from Ireland Fedex Priort'!E17),_xlfn.CEILING.MATH('Rates from Ireland Fedex Priort'!E17,1)+IF($A18="EU",Variables!$B$6,Variables!$B$3),'Rates from Ireland Fedex Priort'!E17) -> 69 | F18: =IF(ISNUMBER('Rates from Ireland Fedex Priort'!F17),_xlfn.CEILING.MATH('Rates from Ireland Fedex Priort'!F17,1)+IF($A18="EU",Variables!$B$6,Variables!$B$3),'Rates from Ireland Fedex Priort'!F17) -> 72 | G18: =IF(ISNUMBER('Rates from Ireland Fedex Priort'!G17),_xlfn.CEILING.MATH('Rates from Ireland Fedex Priort'!G17,1)+IF($A18="EU",Variables!$B$6,Variables!$B$3),'Rates from Ireland Fedex Priort'!G17) -> 86 | H18: =IF(ISNUMBER('Rates from Ireland Fedex Priort'!H17),_xlfn.CEILING.MATH('Rates from Ireland Fedex Priort'!H17,1)+IF($A18="EU",Variables!$B$6,Variables!$B$3),'Rates from Ireland Fedex Priort'!H17) -> 111 | I18: =IF(ISNUMBER('Rates from Ireland Fedex Priort'!I17),_xlfn.CEILING.MATH('Rates from Ireland Fedex Priort'!I17,1)+IF($A18="EU",Variables!$B$6,Variables!$B$3),'Rates from Ireland Fedex Priort'!I17) -> 174 | J18: =IF(ISNUMBER('Rates from Ireland Fedex Priort'!J17),_xlfn.CEILING.MATH('Rates from Ireland Fedex Priort'!J17,1)+IF($A18="EU",Variables!$B$6,Variables!$B$3),'Rates from Ireland Fedex Priort'!J17) -> No service | K18: =IF(ISNUMBER('Rates from Ireland Fedex Priort'!K17),_xlfn.CEILING.MATH('Rates from Ireland Fedex Priort'!K17,1)+IF($A18="EU",Variables!$B$6,Variables!$B$3),'Rates from Ireland Fedex Priort'!K17) -> No service | L18: =IF(ISNUMBER('Rates from Ireland Fedex Priort'!L17),_xlfn.CEILING.MATH('Rates from Ireland Fedex Priort'!L17,1)+IF($A18="EU",Variables!$B$6,Variables!$B$3),'Rates from Ireland Fedex Priort'!L17) -> No service | ... N18: =IF(ISNUMBER('Rates from Ireland Fedex Priort'!N17),_xlfn.CEILING.MATH('Rates from Ireland Fedex Priort'!N17,1)+IF($A18="EU",Variables!$B$6,Variables!$B$3),'Rates from Ireland Fedex Priort'!N17) -> No service | O18: 3 Days | P18: 3-4 Days | Q18: 80 | R18: 4/5* | S18: FedEx Economy | T18: Economy
... A20: =IF('Rates from Ireland Fedex Priort'!A19="","",'Rates from Ireland Fedex Priort'!A19) -> EU | B20: =IF('Rates from Ireland Fedex Priort'!B19="","",'Rates from Ireland Fedex Priort'!B19) -> Ireland | C20: =IF('Rates from Ireland Fedex Priort'!C19="","",'Rates from Ireland Fedex Priort'!C19) -> Barbados | D20: =IF(ISNUMBER('Rates from Ireland Fedex Priort'!D19),_xlfn.CEILING.MATH('Rates from Ireland Fedex Priort'!D19,1)+IF($A20="EU",Variables!$B$5,Variables!$B$2),'Rates from Ireland Fedex Priort'!D19) -> 68 | E20: =IF(ISNUMBER('Rates from Ireland Fedex Priort'!E19),_xlfn.CEILING.MATH('Rates from Ireland Fedex Priort'!E19,1)+IF($A20="EU",Variables!$B$6,Variables!$B$3),'Rates from Ireland Fedex Priort'!E19) -> 77 | F20: =IF(ISNUMBER('Rates from Ireland Fedex Priort'!F19),_xlfn.CEILING.MATH('Rates from Ireland Fedex Priort'!F19,1)+IF($A20="EU",Variables!$B$6,Variables!$B$3),'Rates from Ireland Fedex Priort'!F19) -> 81 | G20: =IF(ISNUMBER('Rates from Ireland Fedex Priort'!G19),_xlfn.CEILING.MATH('Rates from Ireland Fedex Priort'!G19,1)+IF($A20="EU",Variables!$B$6,Variables!$B$3),'Rates from Ireland Fedex Priort'!G19) -> 96 | H20: =IF(ISNUMBER('Rates from Ireland Fedex Priort'!H19),_xlfn.CEILING.MATH('Rates from Ireland Fedex Priort'!H19,1)+IF($A20="EU",Variables!$B$6,Variables!$B$3),'Rates from Ireland Fedex Priort'!H19) -> 117 | I20: =IF(ISNUMBER('Rates from Ireland Fedex Priort'!I19),_xlfn.CEILING.MATH('Rates from Ireland Fedex Priort'!I19,1)+IF($A20="EU",Variables!$B$6,Variables!$B$3),'Rates from Ireland Fedex Priort'!I19) -> 219 | J20: =IF(ISNUMBER('Rates from Ireland Fedex Priort'!J19),_xlfn.CEILING.MATH('Rates from Ireland Fedex Priort'!J19,1)+IF($A20="EU",Variables!$B$6,Variables!$B$3),'Rates from Ireland Fedex Priort'!J19) -> No service | K20: =IF(ISNUMBER('Rates from Ireland Fedex Priort'!K19),_xlfn.CEILING.MATH('Rates from Ireland Fedex Priort'!K19,1)+IF($A20="EU",Variables!$B$6,Variables!$B$3),'Rates from Ireland Fedex Priort'!K19) -> No service | L20: =IF(ISNUMBER('Rates from Ireland Fedex Priort'!L19),_xlfn.CEILING.MATH('Rates from Ireland Fedex Priort'!L19,1)+IF($A20="EU",Variables!$B$6,Variables!$B$3),'Rates from Ireland Fedex Priort'!L19) -> No service | ... N20: =IF(ISNUMBER('Rates from Ireland Fedex Priort'!N19),_xlfn.CEILING.MATH('Rates from Ireland Fedex Priort'!N19,1)+IF($A20="EU",Variables!$B$6,Variables!$B$3),'Rates from Ireland Fedex Priort'!N19) -> No service | O20: 5 Days | P20: 8 Days | Q20: 80 | R20: 4/5* | S20: FedEx Economy | T20: Economy
A21: =IF('Rates from Ireland Fedex Priort'!A20="","",'Rates from Ireland Fedex Priort'!A20) -> EU | B21: =IF('Rates from Ireland Fedex Priort'!B20="","",'Rates from Ireland Fedex Priort'!B20) -> Ireland | C21: =IF('Rates from Ireland Fedex Priort'!C20="","",'Rates from Ireland Fedex Priort'!C20) -> Belarus | D21: =IF(ISNUMBER('Rates from Ireland Fedex Priort'!D20),_xlfn.CEILING.MATH('Rates from Ireland Fedex Priort'!D20,1)+IF($A21="EU",Variables!$B$5,Variables!$B$2),'Rates from Ireland Fedex Priort'!D20) -> No service | E21: =IF(ISNUMBER('Rates from Ireland Fedex Priort'!E20),_xlfn.CEILING.MATH('Rates from Ireland Fedex Priort'!E20,1)+IF($A21="EU",Variables!$B$6,Variables!$B$3),'Rates from Ireland Fedex Priort'!E20) -> No service | F21: =IF(ISNUMBER('Rates from Ireland Fedex Priort'!F20),_xlfn.CEILING.MATH('Rates from Ireland Fedex Priort'!F20,1)+IF($A21="EU",Variables!$B$6,Variables!$B$3),'Rates from Ireland Fedex Priort'!F20) -> No service | G21: =IF(ISNUMBER('Rates from Ireland Fedex Priort'!G20),_xlfn.CEILING.MATH('Rates from Ireland Fedex Priort'!G20,1)+IF($A21="EU",Variables!$B$6,Variables!$B$3),'Rates from Ireland Fedex Priort'!G20) -> No service | H21: =IF(ISNUMBER('Rates from Ireland Fedex Priort'!H20),_xlfn.CEILING.MATH('Rates from Ireland Fedex Priort'!H20,1)+IF($A21="EU",Variables!$B$6,Variables!$B$3),'Rates from Ireland Fedex Priort'!H20) -> No service | I21: =IF(ISNUMBER('Rates from Ireland Fedex Priort'!I20),_xlfn.CEILING.MATH('Rates from Ireland Fedex Priort'!I20,1)+IF($A21="EU",Variables!$B$6,Variables!$B$3),'Rates from Ireland Fedex Priort'!I20) -> No service | J21: =IF(ISNUMBER('Rates from Ireland Fedex Priort'!J20),_xlfn.CEILING.MATH('Rates from Ireland Fedex Priort'!J20,1)+IF($A21="EU",Variables!$B$6,Variables!$B$3),'Rates from Ireland Fedex Priort'!J20) -> No service | K21: =IF(ISNUMBER('Rates from Ireland Fedex Priort'!K20),_xlfn.CEILING.MATH('Rates from Ireland Fedex Priort'!K20,1)+IF($A21="EU",Variables!$B$6,Variables!$B$3),'Rates from Ireland Fedex Priort'!K20) -> No service | L21: =IF(ISNUMBER('Rates from Ireland Fedex Priort'!L20),_xlfn.CEILING.MATH('Rates from Ireland Fedex Priort'!L20,1)+IF($A21="EU",Variables!$B$6,Variables!$B$3),'Rates from Ireland Fedex Priort'!L20) -> No service | ... N21: =IF(ISNUMBER('Rates from Ireland Fedex Priort'!N20),_xlfn.CEILING.MATH('Rates from Ireland Fedex Priort'!N20,1)+IF($A21="EU",Variables!$B$6,Variables!$B$3),'Rates from Ireland Fedex Priort'!N20) -> No service | S21: FedEx Economy | T21: Economy
A22: =IF('Rates from Ireland Fedex Priort'!A21="","",'Rates from Ireland Fedex Priort'!A21) -> EU | B22: =IF('Rates from Ireland Fedex Priort'!B21="","",'Rates from Ireland Fedex Priort'!B21) -> Ireland | C22: =IF('Rates from Ireland Fedex Priort'!C21="","",'Rates from Ireland Fedex Priort'!C21) -> Belgium | D22: =IF(ISNUMBER('Rates from Ireland Fedex Priort'!D21),_xlfn.CEILING.MATH('Rates from Ireland Fedex Priort'!D21,1)+IF($A22="EU",Variables!$B$5,Variables!$B$2),'Rates from Ireland Fedex Priort'!D21) -> 62 | E22: =IF(ISNUMBER('Rates from Ireland Fedex Priort'!E21),_xlfn.CEILING.MATH('Rates from Ireland Fedex Priort'!E21,1)+IF($A22="EU",Variables!$B$6,Variables!$B$3),'Rates from Ireland Fedex Priort'!E21) -> 64 | F22: =IF(ISNUMBER('Rates from Ireland Fedex Priort'!F21),_xlfn.CEILING.MATH('Rates from Ireland Fedex Priort'!F21,1)+IF($A22="EU",Variables!$B$6,Variables!$B$3),'Rates from Ireland Fedex Priort'!F21) -> 67 | G22: =IF(ISNUMBER('Rates from Ireland Fedex Priort'!G21),_xlfn.CEILING.MATH('Rates from Ireland Fedex Priort'!G21,1)+IF($A22="EU",Variables!$B$6,Variables!$B$3),'Rates from Ireland Fedex Priort'!G21) -> 69 | H22: =IF(ISNUMBER('Rates from Ireland Fedex Priort'!H21),_xlfn.CEILING.MATH('Rates from Ireland Fedex Priort'!H21,1)+IF($A22="EU",Variables!$B$6,Variables!$B$3),'Rates from Ireland Fedex Priort'!H21) -> 72 | I22: =IF(ISNUMBER('Rates from Ireland Fedex Priort'!I21),_xlfn.CEILING.MATH('Rates from Ireland Fedex Priort'!I21,1)+IF($A22="EU",Variables!$B$6,Variables!$B$3),'Rates from Ireland Fedex Priort'!I21) -> 77 | J22: =IF(ISNUMBER('Rates from Ireland Fedex Priort'!J21),_xlfn.CEILING.MATH('Rates from Ireland Fedex Priort'!J21,1)+IF($A22="EU",Variables!$B$6,Variables!$B$3),'Rates from Ireland Fedex Priort'!J21) -> 85 | K22: =IF(ISNUMBER('Rates from Ireland Fedex Priort'!K21),_xlfn.CEILING.MATH('Rates from Ireland Fedex Priort'!K21,1)+IF($A22="EU",Variables!$B$6,Variables!$B$3),'Rates from Ireland Fedex Priort'!K21) -> 92 | L22: =IF(ISNUMBER('Rates from Ireland Fedex Priort'!L21),_xlfn.CEILING.MATH('Rates from Ireland Fedex Priort'!L21,1)+IF($A22="EU",Variables!$B$6,Variables!$B$3),'Rates from Ireland Fedex Priort'!L21) -> 119 | ... N22: =IF(ISNUMBER('Rates from Ireland Fedex Priort'!N21),_xlfn.CEILING.MATH('Rates from Ireland Fedex Priort'!N21,1)+IF($A22="EU",Variables!$B$6,Variables!$B$3),'Rates from Ireland Fedex Priort'!N21) -> 132 | O22: 3 Days | P22: 5 Days | Q22: 80 | R22: 4/5* | S22: FedEx Economy | T22: Economy
