Workbook

Sheet Rates from Ireland Fedex Econom
A1: ZONE | B1: Ship From | C1: Ship To | D1: Doc 0.5kg | E1: Paket 1kg | F1: Paket 2kg | G1: Box 5kg | H1: Box 10kg | I1: Box 15kg | J1: Box 20kg | K1: Box 25kg | L1: Suitcase 10kg | M1: Suitcase 20kg | N1: Suitcase 30kg | O1: Days ENV | P1: Days PARCEL | Q1: Insurance | R1: Rating | S1: Courier | T1: Service
A2: EU | B2: Ireland | C2: Afghanistan | D2: No service | E2: No service | F2: No service | G2: No service | H2: No service | I2: No service | J2: No service | K2: No service | L2: No service | M2: No service | N2: No service
A3: EU | B3: Ireland | C3: Albania | D3: 35.5 | E3: 35.5 | F3: 37.9 | G3: 45.5 | H3: 49 | I3: 55 | J3: 62 | K3: 69 | L3: 99 | M3: 105 | N3: 115 | O3: 8 Days | P3: 9 Days | Q3: 80 | R3: 4/5* | S3: FedEx Economy | T3: Economy
A4: EU | B4: Ireland | C4: Algeria | D4: 21.06 | E4: 22.46 | F4: 25.33 | G4: 36.04 | H4: 56.28 | I4: 106.58 | J4: 139.48 | K4: 175.68 | L4: 76.28 | M4: 159.48 | N4: 225.3 | O4: 3 Days | P4: 3-4 Days | Q4: 80 | R4: 4/5* | S4: FedEx Economy | T4: Economy
A5: EU | B5: Ireland | C5: American Samoa (US) | D5: 31.72 | E5: 33.75 | F5: 37.9 | G5: 52.36 | H5: No service | I5: No service | J5: No service | K5: No service | L5: No service | M5: No service | N5: No service | S5: FedEx Economy | T5: Economy
A6: EU | B6: Ireland | C6: Andorra | D6: 23 | E6: 19.7 | F6: 20 | G6: 21 | H6: 24.5 | I6: 30 | J6: 38 | K6: 42 | L6: 42 | M6: 67.5 | N6: 69 | O6: 6 Days | P6: 8 Days | Q6: 80 | R6: 4/5* | S6: FedEx Economy | T6: Economy
A7: EU | B7: Ireland | C7: Angola | D7: 31.72 | E7: 33.75 | F7: 37.9 | G7: 52.36 | H7: 74.7 | I7: 161.46 | J7: 211.93 | K7: 261.19 | L7: 94.7 | M7: 231.93 | N7: 330.21 | O7: 2-4 Days | P7: 2-5 Days | Q7: 80 | R7: 4/5* | S7: FedEx Economy | T7: Economy
A8: EU | B8: Ireland | C8: Anguilla | D8: 27.47 | E8: 28.9 | F8: 32.01 | G8: 44.79 | H8: 61.2 | I8: 142.62 | J8: 193.23 | K8: 212.93 | L8: 81.2 | M8: 213.23 | N8: 305.25 | O8: 7 Days | P8: 12-14 Days | Q8: 80 | R8: 4/5* | S8: FedEx Economy | T8: Economy
A9: EU | B9: Ireland | C9: Antigua and Barbuda | D9: 27.47 | E9: 28.9 | F9: 32.01 | G9: 44.79 | H9: 61.2 | I9: 142.62 | J9: 193.23 | K9: 212.93 | L9: 81.2 | M9: 213.23 | N9: 305.25 | O9: 5 Days | P9: 8 Days | Q9: 80 | R9: 4/5* | S9: FedEx Economy | T9: Economy
A10: EU | B10: Ireland | C10: Argentina | D10: 27.47 | E10: 28.9 | F10: 32.01 | G10: 44.79 | H10: 61.2 | I10: 142.62 | J10: 193.23 | K10: 212.93 | L10: 81.2 | M10: 213.23 | N10: 305.25 | O10: 5 Days | P10: 8 Days | Q10: 80 | R10: 4/5* | S10: FedEx Economy | T10: Economy
A11: EU | B11: Ireland | C11: Armenia | D11: 21.06 | E11: 22.46 | F11: 25.33 | G11: 36.04 | H11: 56.28 | I11: 106.58 | J11: 139.48 | K11: 175.68 | L11: 86.28 | M11: 179.48 | N11: 245.3 | O11: 3 Days | P11: 3-4 Days | Q11: 80 | R11: 4/5* | S11: FedEx Economy | T11: Economy
A12: EU | B12: Ireland | C12: Aruba (Netherlands) | D12: 27.47 | E12: 28.9 | F12: 32.01 | G12: 44.79 | H12: 61.2 | I12: 142.62 | J12: 193.23 | K12: 212.93 | L12: 81.2 | M12: 213.23 | N12: 305.25 | O12: 5 Days | P12: 8 Days | Q12: 80 | R12: 4/5* | S12: FedEx Economy | T12: Economy
A13: EU | B13: Ireland | C13: Australia | D13: 47.67 | E13: 51 | F13: 57.86 | G13: 86.22 | H13: 122.52 | I13: 188 | J13: 247.16 | K13: 306.73 | L13: 142.52 | M13: 203.23 | N13: 386.3 | O13: 5 Days | P13: 8 Days | Q13: 80 | R13: 4/5* | S13: FedEx Economy | T13: Economy
A14: EU | B14: Ireland | C14: Austria | D14: 23 | E14: 19.7 | F14: 20 | G14: 21 | H14: 24.5 | I14: 30 | J14: 38 | K14: 42 | L14: 42 | M14: 67.5 | N14: 69 | O14: 3 Days | P14: 8 Days | Q14: 80 | R14: 4/5* | S14: FedEx Economy | T14: Economy
A15: EU | B15: Ireland | C15: Azerbaijan | D15: 21.06 | E15: 22.46 | F15: 25.33 | G15: 36.04 | H15: 56.28 | I15: 106.58 | J15: 139.48 | K15: 175.68 | L15: 76.28 | M15: 159.48 | N15: 225.3 | O15: 3 Days | P15: 3-4 Days | Q15: 80 | R15: 4/5* | S15: FedEx Economy | T15: Economy
A16: EU | B16: Ireland | C16: Bahamas | D16: 27.47 | E16: 28.9 | F16: 32.01 | G16: 44.79 | H16: 61.2 | I16: 142.62 | J16: 193.23 | K16: 212.93 | L16: 81.2 | M16: 213.23 | N16: 305.25 | O16: 5 Days | P16: 8 Days | Q16: 80 | R16: 4/5* | S16: FedEx Economy | T16: Economy
A17: EU | B17: Ireland | C17: Bahrain | D17: 21.06 | E17: 22.46 | F17: 25.33 | G17: 36.04 | H17: 56.28 | I17: 106.58 | J17: 139.48 | K17: 175.68 | L17: 76.28 | M17: 159.48 | N17: 225.3 | O17: 3 Days | P17: 3-4 Days | Q17: 80 | R17: 4/5* | S17: FedEx Economy | T17: Economy
... A19: EU | B19: Ireland | C19: Barbados | D19: 27.47 | E19: 28.9 | F19: 32.01 | G19: 44.79 | H19: 61.2 | I19: 142.62 | J19: 193.23 | K19: 212.93 | L19: 81.2 | M19: 213.23 | N19: 305.25 | O19: 5 Days | P19: 8 Days | Q19: 80 | R19: 4/5* | S19: FedEx Economy | T19: Economy
A20: EU | B20: Ireland | C20: Belarus | D20: No service | E20: No service | F20: No service | G20: No service | H20: No service | I20: No service | J20: No service | K20: No service | L20: No service | M20: No service | N20: No service | S20: FedEx Economy | T20: Economy
A21: EU | B21: Ireland | C21: Belgium | D21: 21.5 | E21: 19.1 | F21: 21 | G21: 23 | H21: 25 | I21: 29 | J21: 36 | K21: 41 | L21: 63 | M21: 69 | N21: 73 | O21: 3 Days | P21: 5 Days | Q21: 80 | R21: 4/5* | S21: FedEx Economy | T21: Economy
A22: EU | B22: Ireland | C22: Belize | D22: 27.47 | E22: 28.9 | F22: 32.01 | G22: 44.79 | H22: 61.2 | I22: 142.62 | J22: 193.23 | K22: 212.93 | L22: 81.2 | M22: 213.23 | N22: 305.25 | O22: 5 Days | P22: 8 Days | Q22: 80 | R22: 4/5* | S22: FedEx Economy | T22: Economy
A23: EU | B23: Ireland | C23: Benin | D23: 34.52 | E23: 33.75 | F23: 37.9 | G23: 52.36 | H23: 74.7 | I23: 161.46 | J23: 211.93 | K23: 261.19 | L23: 94.7 | M23: 231.53 | N23: 330.31 | O23: 5 Days | P23: 9 Days | Q23: 80 | R23: 4/5* | S23: FedEx Economy | T23: Economy
A24: EU | B24: Ireland | C24: Bermuda (BOT) | D24: 27.47 | E24: 28.9 | F24: 32.01 | G24: 44.79 | H24: 61.2 | I24: 142.62 | J24: 193.23 | K24: 212.93 | L24: 81.2 | M24: 213.23 | N24: 305.25 | O24: 5 Days | P24: 8 Days | Q24: 80 | R24: 4/5* | S24: FedEx Economy | T24: Economy
A25: EU | B25: Ireland | C25: Bhutan | D25: 21.06 | E25: 22.46 | F25: 25.33 | G25: 36.04 | H25: 56.28 | I25: 106.58 | J25: 139.48 | K25: 175.68 | L25: 76.28 | M25: 159.48 | N25: 225.3 | O25: 3 Days | P25: 3-4 Days | Q25: 80 | R25: 4/5* | S25: FedEx Economy | T25: Economy
A26: EU | B26: Ireland | C26: Bolivia | D26: 30.11 | E26: 28.9 | F26: 32.01 | G26: 44.79 | H26: 61.2 | I26: 142.62 | J26: 193.23 | K26: 239.48 | L26: 81.2 | M26: 213.23 | N26: 305.25 | O26: 8 Days | P26: 9 Days | Q26: 80 | R26: 4/5* | S26: FedEx Economy | T26: Economy
A27: EU | B27: Ireland | C27: Bonaire | D27: 30.11 | E27: 28.9 | F27: 32.01 | G27: 44.79 | H27: 61.2 | I27: 142.62 | J27: 193.23 | K27: 239.48 | L27: 81.2 | M27: 213.23 | N27: 305.25 | O27: 8 Days | P27: 9 Days | Q27: 80 | R27: 4/5* | S27: FedEx Economy | T27: Economy
A28: EU | B28: Ireland | C28: Bosnia and Herzegovina | D28: 35.5 | E28: 35.5 | F28: 37.9 | G28: 45.5 | H28: 49 | I28: 55 | J28: 62 | K28: 69 | L28: 79 | M28: 85 | N28: 95 | O28: 3 Days | P28: 4 Days | Q28: 80 | R28: 4/5* | S28: FedEx Economy | T28: Economy
A29: EU | B29: Ireland | C29: Botswana | D29: 31.72 | E29: 33.75 | F29: 37.9 | G29: 52.36 | H29: 74.7 | I29: 161.46 | J29: 211.93 | K29: 261.19 | L29: 94.7 | M29: 231.93 | N29: 330.21 | O29: 2-4 Days | P29: 2-5 Days | Q29: 80 | R29: 4/5* | S29: FedEx Economy | T29: Economy
A30: EU | B30: Ireland | C30: Brazil | D30: 27.47 | E30: 28.9 | F30: 32.01 | G30: 44.79 | H30: 61.2 | I30: 142.62 | J30: 193.23 | K30: 212.93 | L30: 81.2 | M30: 213.23 | N30: 305.25 | O30: 5 Days | P30: 8 Days | Q30: 80 | R30: 4/5* | S30: FedEx Economy | T30: Economy
A31: EU | B31: Ireland | C31: British Virgin Islands | D31: 30.11 | E31: 28.9 | F31: 32.01 | G31: 44.79 | H31: 61.2 | I31: 142.62 | J31: 193.23 | K31: 239.48 | L31: 81.2 | M31: 213.23 | N31: 305.25 | O31: 8 Days | P31: 9 Days | Q31: 80 | R31: 4/5* | S31: FedEx Economy | T31: Economy
A32: EU | B32: Ireland | C32: Brunei | D32: 21.06 | E32: 22.46 | F32: 25.33 | G32: 36.04 | H32: 56.28 | I32: 106.58 | J32: 139.48 | K32: 175.68 | L32: 76.28 | M32: 159.48 | N32: 225.3 | O32: 3 Days | P32: 3-4 Days | Q32: 80 | R32: 4/5* | S32: FedEx Economy | T32: Economy
... A40: EU | B40: Ireland | C40: Cayman Islands | D40: 27.47 | E40: 28.9 | F40: 32.01 | G40: 44.79 | H40: 61.2 | I40: 142.62 | J40: 193.23 | K40: 212.93 | L40: 81.2 | M40: 213.23 | N40: 305.25 | O40: 5 Days | P40: 8 Days | Q40: 80 | R40: 4/5* | S40: FedEx Economy | T40: Economy
A41: EU | B41: Ireland | C41: Central African Republic | D41: No service | E41: No service | F41: No service | G41: No service | H41: No service | I41: No service | J41: No service | K41: No service | L41: No service | M41: No service | N41: No service | S41: FedEx Economy | T41: Economy
A42: EU | B42: Ireland | C42: Chad | D42: 31.72 | E42: 33.75 | F42: 37.9 | G42: 52.36 | H42: 74.7 | I42: 161.46 | J42: 211.93 | K42: 261.19 | L42: 94.7 | M42: 231.93 | N42: 330.21 | O42: 2-4 Days | P42: 2-5 Days | Q42: 80 | R42: 4/5* | S42: FedEx Economy | T42: Economy
A43: EU | B43: Ireland | C43: Chile | D43: 27.47 | E43: 28.9 | F43: 32.01 | G43: 44.79 | H43: 61.2 | I43: 142.62 | J43: 193.23 | K43: 212.93 | L43: 81.2 | M43: 213.23 | N43: 305.25 | O43: 5 Days | P43: 8 Days | Q43: 80 | R43: 4/5* | S43: FedEx Economy | T43: Economy
A44: EU | B44: Ireland | C44: China | D44: 18.61 | E44: 48.34 | F44: 50.89 | G44: 61.24 | H44: 72.42 | I44: 124.48 | J44: 156.66 | K44: 187.1 | L44: 92.42 | M44: 177 | N44: 237.37 | O44: 3-4 Days | P44: 10 Days | Q44: 80 | S44: FedEx Economy | T44: Economy
A45: EU | B45: Ireland | C45: Christmas Island | D45: No service | E45: No service | F45: No service | G45: No service | H45: No service | I45: No service | J45: No service | K45: No service | L45: No service | M45: No service | N45: No service | S45: FedEx Economy | T45: Economy
A46: EU | B46: Ireland | C46: Cocos (Keeling) Islands | D46: No service | E46: No service | F46: No service | G46: No service | H46: No service | I46: No service | J46: No service | K46: No service | L46: No service | M46: No service | N46: No service | S46: FedEx Economy | T46: Economy
A47: EU | B47: Ireland | C47: Colombia | D47: 27.47 | E47: 28.9 | F47: 32.01 | G47: 44.79 | H47: 61.2 | I47: 142.62 | J47: 193.23 | K47: 212.93 | L47: 81.2 | M47: 213.23 | N47: 305.25 | O47: 5 Days | P47: 8 Days | Q47: 80 | R47: 4/5* | S47: FedEx Economy | T47: Economy
A48: EU | B48: Ireland | C48: Comoros | D48: No service | E48: No service | F48: No service | G48: No service | H48: No service | I48: No service | J48: No service | K48: No service | L48: No service | M48: No service | N48: No service | S48: FedEx Economy | T48: Economy
...

Sheet Result
A1: Type | B1: Ship From | C1: Ship To | D1: Doc 0.5kg | E1: Paket 1kg | F1: Paket 2kg | G1: Box 5kg | H1: Box 10kg | I1: Box 15kg | J1: Box 20kg | K1: Box 25kg | L1: Suitcase 10kg | M1: Suitcase 20kg | N1: Suitcase 30kg | O1: Days ENV | P1: Days PARCEL | Q1: Insurance | R1: Rating | S1: Courier | T1: Service
A3: =IF('Rates from Ireland Fedex Econom'!A2="","",'Rates from Ireland Fedex Econom'!A2) -> EU | B3: =IF('Rates from Ireland Fedex Econom'!B2="","",'Rates from Ireland Fedex Econom'!B2) -> Ireland | C3: =IF('Rates from Ireland Fedex Econom'!C2="","",'Rates from Ireland Fedex Econom'!C2) -> Afghanistan | D3: =IF(ISNUMBER('Rates from Ireland Fedex Econom'!D2),_xlfn.CEILING.MATH('Rates from Ireland Fedex Econom'!D2,1)+(IF($A3="EU",Variables!$B$5,IF($A3="N/A",0,Variables!$B$2))),'Rates from Ireland Fedex Econom'!D2) -> No service | E3: =IF(ISNUMBER('Rates from Ireland Fedex Econom'!E2),_xlfn.CEILING.MATH('Rates from Ireland Fedex Econom'!E2,1)+(IF($A3="EU",Variables!$B$6,IF($A3="N/A",0,Variables!$B$3))),'Rates from Ireland Fedex Econom'!E2) -> No service | F3: =IF(ISNUMBER('Rates from Ireland Fedex Econom'!F2),_xlfn.CEILING.MATH('Rates from Ireland Fedex Econom'!F2,1)+(IF($A3="EU",Variables!$B$6,IF($A3="N/A",0,Variables!$B$3))),'Rates from Ireland Fedex Econom'!F2) -> No service | G3: =IF(ISNUMBER('Rates from Ireland Fedex Econom'!G2),_xlfn.CEILING.MATH('Rates from Ireland Fedex Econom'!G2,1)+(IF($A3="EU",Variables!$B$6,IF($A3="N/A",0,Variables!$B$3))),'Rates from Ireland Fedex Econom'!G2) -> No service | H3: =IF(ISNUMBER('Rates from Ireland Fedex Econom'!H2),_xlfn.CEILING.MATH('Rates from Ireland Fedex Econom'!H2,1)+(IF($A3="EU",Variables!$B$6,IF($A3="N/A",0,Variables!$B$3))),'Rates from Ireland Fedex Econom'!H2) -> No service | I3: =IF(ISNUMBER('Rates from Ireland Fedex Econom'!I2),_xlfn.CEILING.MATH('Rates from Ireland Fedex Econom'!I2,1)+(IF($A3="EU",Variables!$B$6,IF($A3="N/A",0,Variables!$B$3))),'Rates from Ireland Fedex Econom'!I2) -> No service | J3: =IF(ISNUMBER('Rates from Ireland Fedex Econom'!J2),_xlfn.CEILING.MATH('Rates from Ireland Fedex Econom'!J2,1)+(IF($A3="EU",Variables!$B$6,IF($A3="N/A",0,Variables!$B$3))),'Rates from Ireland Fedex Econom'!J2) -> No service | K3: =IF(ISNUMBER('Rates from Ireland Fedex Econom'!K2),_xlfn.CEILING.MATH('Rates from Ireland Fedex Econom'!K2,1)+(IF($A3="EU",Variables!$B$6,IF($A3="N/A",0,Variables!$B$3))),'Rates from Ireland Fedex Econom'!K2) -> No service | L3: =IF(ISNUMBER('Rates from Ireland Fedex Econom'!L2),_xlfn.CEILING.MATH('Rates from Ireland Fedex Econom'!L2,1)+(IF($A3="EU",Variables!$B$6,IF($A3="N/A",0,Variables!$B$3))),'Rates from Ireland Fedex Econom'!L2) -> No service | ... N3: =IF(ISNUMBER('Rates from Ireland Fedex Econom'!N2),_xlfn.CEILING.MATH('Rates from Ireland Fedex Econom'!N2,1)+(IF($A3="EU",Variables!$B$6,IF($A3="N/A",0,Variables!$B$3))),'Rates from Ireland Fedex Econom'!N2) -> No service | O3: =IF('Rates from Ireland Fedex Econom'!O2="","",'Rates from Ireland Fedex Econom'!O2) | P3: =IF('Rates from Ireland Fedex Econom'!P2="","",'Rates from Ireland Fedex Econom'!P2) | Q3: =IF('Rates from Ireland Fedex Econom'!Q2="","",'Rates from Ireland Fedex Econom'!Q2) | R3: =IF('Rates from Ireland Fedex Econom'!R2="","",'Rates from Ireland Fedex Econom'!R2) | S3: =IF('Rates from Ireland Fedex Econom'!S2="","",'Rates from Ireland Fedex Econom'!S2) | T3: =IF('Rates from Ireland Fedex Econom'!T2="","",'Rates from Ireland Fedex Econom'!T2)
A4: =IF('Rates from Ireland Fedex Econom'!A3="","",'Rates from Ireland Fedex Econom'!A3) -> EU | B4: =IF('Rates from Ireland Fedex Econom'!B3="","",'Rates from Ireland Fedex Econom'!B3) -> Ireland | C4: =IF('Rates from Ireland Fedex Econom'!C3="","",'Rates from Ireland Fedex Econom'!C3) -> Albania | D4: =IF(ISNUMBER('Rates from Ireland Fedex Econom'!D3),_xlfn.CEILING.MATH('Rates from Ireland Fedex Econom'!D3,1)+(IF($A4="EU",Variables!$B$5,IF($A4="N/A",0,Variables!$B$2))),'Rates from Ireland Fedex Econom'!D3) -> 66 | E4: =IF(ISNUMBER('Rates from Ireland Fedex Econom'!E3),_xlfn.CEILING.MATH('Rates from Ireland Fedex Econom'!E3,1)+(IF($A4="EU",Variables!$B$6,IF($A4="N/A",0,Variables!$B$3))),'Rates from Ireland Fedex Econom'!E3) -> 81 | F4: =IF(ISNUMBER('Rates from Ireland Fedex Econom'!F3),_xlfn.CEILING.MATH('Rates from Ireland Fedex Econom'!F3,1)+(IF($A4="EU",Variables!$B$6,IF($A4="N/A",0,Variables!$B$3))),'Rates from Ireland Fedex Econom'!F3) -> 83 | G4: =IF(ISNUMBER('Rates from Ireland Fedex Econom'!G3),_xlfn.CEILING.MATH('Rates from Ireland Fedex Econom'!G3,1)+(IF($A4="EU",Variables!$B$6,IF($A4="N/A",0,Variables!$B$3))),'Rates from Ireland Fedex Econom'!G3) -> 91 | H4: =IF(ISNUMBER('Rates from Ireland Fedex Econom'!H3),_xlfn.CEILING.MATH('Rates from Ireland Fedex Econom'!H3,1)+(IF($A4="EU",Variables!$B$6,IF($A4="N/A",0,Variables!$B$3))),'Rates from Ireland Fedex Econom'!H3) -> 94 | I4: =IF(ISNUMBER('Rates from Ireland Fedex Econom'!I3),_xlfn.CEILING.MATH('Rates from Ireland Fedex Econom'!I3,1)+(IF($A4="EU",Variables!$B$6,IF($A4="N/A",0,Variables!$B$3))),'Rates from Ireland Fedex Econom'!I3) -> 100 | J4: =IF(ISNUMBER('Rates from Ireland Fedex Econom'!J3),_xlfn.CEILING.MATH('Rates from Ireland Fedex Econom'!J3,1)+(IF($A4="EU",Variables!$B$6,IF($A4="N/A",0,Variables!$B$3))),'Rates from Ireland Fedex Econom'!J3) -> 107 | K4: =IF(ISNUMBER('Rates from Ireland Fedex Econom'!K3),_xlfn.CEILING.MATH('Rates from Ireland Fedex Econom'!K3,1)+(IF($A4="EU",Variables!$B$6,IF($A4="N/A",0,Variables!$B$3))),'Rates from Ireland Fedex Econom'!K3) -> 114 | L4: =IF(ISNUMBER('Rates from Ireland Fedex Econom'!L3),_xlfn.CEILING.MATH('Rates from Ireland Fedex Econom'!L3,1)+(IF($A4="EU",Variables!$B$6,IF($A4="N/A",0,Variables!$B$3))),'Rates from Ireland Fedex Econom'!L3) -> 144 | ... N4: =IF(ISNUMBER('Rates from Ireland Fedex Econom'!N3),_xlfn.CEILING.MATH('Rates from Ireland Fedex Econom'!N3,1)+(IF($A4="EU",Variables!$B$6,IF($A4="N/A",0,Variables!$B$3))),'Rates from Ireland Fedex Econom'!N3) -> 160 | O4: =IF('Rates from Ireland Fedex Econom'!O3="","",'Rates from Ireland Fedex Econom'!O3) -> 8 Days | P4: =IF('Rates from Ireland Fedex Econom'!P3="","",'Rates from Ireland Fedex Econom'!P3) -> 9 Days | Q4: =IF('Rates from Ireland Fedex Econom'!Q3="","",'Rates from Ireland Fedex Econom'!Q3) -> 80 | R4: =IF('Rates from Ireland Fedex Econom'!R3="","",'Rates from Ireland Fedex Econom'!R3) -> 4/5* | S4: =IF('Rates from Ireland Fedex Econom'!S3="","",'Rates from Ireland Fedex Econom'!S3) -> FedEx Economy | T4: =IF('Rates from Ireland Fedex Econom'!T3="","",'Rates from Ireland Fedex Econom'!T3) -> Economy
A5: =IF('Rates from Ireland Fedex Econom'!A4="","",'Rates from Ireland Fedex Econom'!A4) -> EU | B5: =IF('Rates from Ireland Fedex Econom'!B4="","",'Rates from Ireland Fedex Econom'!B4) -> Ireland | C5: =IF('Rates from Ireland Fedex Econom'!C4="","",'Rates from Ireland Fedex Econom'!C4) -> Algeria | D5: =IF(ISNUMBER('Rates from Ireland Fedex Econom'!D4),_xlfn.CEILING.MATH('Rates from Ireland Fedex Econom'!D4,1)+(IF($A5="EU",Variables!$B$5,IF($A5="N/A",0,Variables!$B$2))),'Rates from Ireland Fedex Econom'!D4) -> 52 | E5: =IF(ISNUMBER('Rates from Ireland Fedex Econom'!E4),_xlfn.CEILING.MATH('Rates from Ireland Fedex Econom'!E4,1)+(IF($A5="EU",Variables!$B$6,IF($A5="N/A",0,Variables!$B$3))),'Rates from Ireland Fedex Econom'!E4) -> 68 | F5: =IF(ISNUMBER('Rates from Ireland Fedex Econom'!F4),_xlfn.CEILING.MATH('Rates from Ireland Fedex Econom'!F4,1)+(IF($A5="EU",Variables!$B$6,IF($A5="N/A",0,Variables!$B$3))),'Rates from Ireland Fedex Econom'!F4) -> 71 | G5: =IF(ISNUMBER('Rates from Ireland Fedex Econom'!G4),_xlfn.CEILING.MATH('Rates from Ireland Fedex Econom'!G4,1)+(IF($A5="EU",Variables!$B$6,IF($A5="N/A",0,Variables!$B$3))),'Rates from Ireland Fedex Econom'!G4) -> 82 | H5: =IF(ISNUMBER('Rates from Ireland Fedex Econom'!H4),_xlfn.CEILING.MATH('Rates from Ireland Fedex Econom'!H4,1)+(IF($A5="EU",Variables!$B$6,IF($A5="N/A",0,Variables!$B$3))),'Rates from Ireland Fedex Econom'!H4) -> 102 | I5: =IF(ISNUMBER('Rates from Ireland Fedex Econom'!I4),_xlfn.CEILING.MATH('Rates from Ireland Fedex Econom'!I4,1)+(IF($A5="EU",Variables!$B$6,IF($A5="N/A",0,Variables!$B$3))),'Rates from Ireland Fedex Econom'!I4) -> 152 | J5: =IF(ISNUMBER('Rates from Ireland Fedex Econom'!J4),_xlfn.CEILING.MATH('Rates from Ireland Fedex Econom'!J4,1)+(IF($A5="EU",Variables!$B$6,IF($A5="N/A",0,Variables!$B$3))),'Rates from Ireland Fedex Econom'!J4) -> 185 | K5: =IF(ISNUMBER('Rates from Ireland Fedex Econom'!K4),_xlfn.CEILING.MATH('Rates from Ireland Fedex Econom'!K4,1)+(IF($A5="EU",Variables!$B$6,IF($A5="N/A",0,Variables!$B$3))),'Rates from Ireland Fedex Econom'!K4) -> 221 | L5: =IF(ISNUMBER('Rates from Ireland Fedex Econom'!L4),_xlfn.CEILING.MATH('Rates from Ireland Fedex Econom'!L4,1)+(IF($A5="EU",Variables!$B$6,IF($A5="N/A",0,Variables!$B$3))),'Rates from Ireland Fedex Econom'!L4) -> 122 | ... N5: =IF(ISNUMBER('Rates from Ireland Fedex Econom'!N4),_xlfn.CEILING.MATH('Rates from Ireland Fedex Econom'!N4,1)+(IF($A5="EU",Variables!$B$6,IF($A5="N/A",0,Variables!$B$3))),'Rates from Ireland Fedex Econom'!N4) -> 271 | O5: =IF('Rates from Ireland Fedex Econom'!O4="","",'Rates from Ireland Fedex Econom'!O4) -> 3 Days | P5: =IF('Rates from Ireland Fedex Econom'!P4="","",'Rates from Ireland Fedex Econom'!P4) -> 3-4 Days | Q5: =IF('Rates from Ireland Fedex Econom'!Q4="","",'Rates from Ireland Fedex Econom'!Q4) -> 80 | R5: =IF('Rates from Ireland Fedex Econom'!R4="","",'Rates from Ireland Fedex Econom'!R4) -> 4/5* | S5: =IF('Rates from Ireland Fedex Econom'!S4="","",'Rates from Ireland Fedex Econom'!S4) -> FedEx Economy | T5: =IF('Rates from Ireland Fedex Econom'!T4="","",'Rates from Ireland Fedex Econom'!T4) -> Economy
A6: =IF('Rates from Ireland Fedex Econom'!A5="","",'Rates from Ireland Fedex Econom'!A5) -> EU | B6: =IF('Rates from Ireland Fedex Econom'!B5="","",'Rates from Ireland Fedex Econom'!B5) -> Ireland | C6: =IF('Rates from Ireland Fedex Econom'!C5="","",'Rates from Ireland Fedex Econom'!C5) -> American Samoa (US) | D6: =IF(ISNUMBER('Rates from Ireland Fedex Econom'!D5),_xlfn.CEILING.MATH('Rates from Ireland Fedex Econom'!D5,1)+(IF($A6="EU",Variables!$B$5,IF($A6="N/A",0,Variables!$B$2))),'Rates from Ireland Fedex Econom'!D5) -> 62 | E6: =IF(ISNUMBER('Rates from Ireland Fedex Econom'!E5),_xlfn.CEILING.MATH('Rates from Ireland Fedex Econom'!E5,1)+(IF($A6="EU",Variables!$B$6,IF($A6="N/A",0,Variables!$B$3))),'Rates from Ireland Fedex Econom'!E5) -> 79 | F6: =IF(ISNUMBER('Rates from Ireland Fedex Econom'!F5),_xlfn.CEILING.MATH('Rates from Ireland Fedex Econom'!F5,1)+(IF($A6="EU",Variables!$B$6,IF($A6="N/A",0,Variables!$B$3))),'Rates from Ireland Fedex Econom'!F5) -> 83 | G6: =IF(ISNUMBER('Rates from Ireland Fedex Econom'!G5),_xlfn.CEILING.MATH('Rates from Ireland Fedex Econom'!G5,1)+(IF($A6="EU",Variables!$B$6,IF($A6="N/A",0,Variables!$B$3))),'Rates from Ireland Fedex Econom'!G5) -> 98 | H6: =IF(ISNUMBER('Rates from Ireland Fedex Econom'!H5),_xlfn.CEILING.MATH('Rates from Ireland Fedex Econom'!H5,1)+(IF($A6="EU",Variables!$B$6,IF($A6="N/A",0,Variables!$B$3))),'Rates from Ireland Fedex Econom'!H5) -> No service | I6: =IF(ISNUMBER('Rates from Ireland Fedex Econom'!I5),_xlfn.CEILING.MATH('Rates from Ireland Fedex Econom'!I5,1)+(IF($A6="EU",Variables!$B$6,IF($A6="N/A",0,Variables!$B$3))),'Rates from Ireland Fedex Econom'!I5) -> No service | J6: =IF(ISNUMBER('Rates from Ireland Fedex Econom'!J5),_xlfn.CEILING.MATH('Rates from Ireland Fedex Econom'!J5,1)+(IF($A6="EU",Variables!$B$6,IF($A6="N/A",0,Variables!$B$3))),'Rates from Ireland Fedex Econom'!J5) -> No service | K6: =IF(ISNUMBER('Rates from Ireland Fedex Econom'!K5),_xlfn.CEILING.MATH('Rates from Ireland Fedex Econom'!K5,1)+(IF($A6="EU",Variables!$B$6,IF($A6="N/A",0,Variables!$B$3))),'Rates from Ireland Fedex Econom'!K5) -> No service | L6: =IF(ISNUMBER('Rates from Ireland Fedex Econom'!L5),_xlfn.CEILING.MATH('Rates from Ireland Fedex Econom'!L5,1)+(IF($A6="EU",Variables!$B$6,IF($A6="N/A",0,Variables!$B$3))),'Rates from Ireland Fedex Econom'!L5) -> No service | ... N6: =IF(ISNUMBER('Rates from Ireland Fedex Econom'!N5),_xlfn.CEILING.MATH('Rates from Ireland Fedex Econom'!N5,1)+(IF($A6="EU",Variables!$B$6,IF($A6="N/A",0,Variables!$B$3))),'Rates from Ireland Fedex Econom'!N5) -> No service | O6: =IF('Rates from Ireland Fedex Econom'!O5="","",'Rates from Ireland Fedex Econom'!O5) | P6: =IF('Rates from Ireland Fedex Econom'!P5="","",'Rates from Ireland Fedex Econom'!P5) | Q6: =IF('Rates from Ireland Fedex Econom'!Q5="","",'Rates from Ireland Fedex Econom'!Q5) | R6: =IF('Rates from Ireland Fedex Econom'!R5="","",'Rates from Ireland Fedex Econom'!R5) | S6: =IF('Rates from Ireland Fedex Econom'!S5="","",'Rates from Ireland Fedex Econom'!S5) -> FedEx Economy | T6: =IF('Rates from Ireland Fedex Econom'!T5="","",'Rates from Ireland Fedex Econom'!T5) -> Economy
A7: =IF('Rates from Ireland Fedex Econom'!A6="","",'Rates from Ireland Fedex Econom'!A6) -> EU | B7: =IF('Rates from Ireland Fedex Econom'!B6="","",'Rates from Ireland Fedex Econom'!B6) -> Ireland | C7: =IF('Rates from Ireland Fedex Econom'!C6="","",'Rates from Ireland Fedex Econom'!C6) -> Andorra | D7: =IF(ISNUMBER('Rates from Ireland Fedex Econom'!D6),_xlfn.CEILING.MATH('Rates from Ireland Fedex Econom'!D6,1)+(IF($A7="EU",Variables!$B$5,IF($A7="N/A",0,Variables!$B$2))),'Rates from Ireland Fedex Econom'!D6) -> 53 | E7: =IF(ISNUMBER('Rates from Ireland Fedex Econom'!E6),_xlfn.CEILING.MATH('Rates from Ireland Fedex Econom'!E6,1)+(IF($A7="EU",Variables!$B$6,IF($A7="N/A",0,Variables!$B$3))),'Rates from Ireland Fedex Econom'!E6) -> 65 | F7: =IF(ISNUMBER('Rates from Ireland Fedex Econom'!F6),_xlfn.CEILING.MATH('Rates from Ireland Fedex Econom'!F6,1)+(IF($A7="EU",Variables!$B$6,IF($A7="N/A",0,Variables!$B$3))),'Rates from Ireland Fedex Econom'!F6) -> 65 | G7: =IF(ISNUMBER('Rates from Ireland Fedex Econom'!G6),_xlfn.CEILING.MATH('Rates from Ireland Fedex Econom'!G6,1)+(IF($A7="EU",Variables!$B$6,IF($A7="N/A",0,Variables!$B$3))),'Rates from Ireland Fedex Econom'!G6) -> 66 | H7: =IF(ISNUMBER('Rates from Ireland Fedex Econom'!H6),_xlfn.CEILING.MATH('Rates from Ireland Fedex Econom'!H6,1)+(IF($A7="EU",Variables!$B$6,IF($A7="N/A",0,Variables!$B$3))),'Rates from Ireland Fedex Econom'!H6) -> 70 | I7: =IF(ISNUMBER('Rates from Ireland Fedex Econom'!I6),_xlfn.CEILING.MATH('Rates from Ireland Fedex Econom'!I6,1)+(IF($A7="EU",Variables!$B$6,IF($A7="N/A",0,Variables!$B$3))),'Rates from Ireland Fedex Econom'!I6) -> 75 | J7: =IF(ISNUMBER('Rates from Ireland Fedex Econom'!J6),_xlfn.CEILING.MATH('Rates from Ireland Fedex Econom'!J6,1)+(IF($A7="EU",Variables!$B$6,IF($A7="N/A",0,Variables!$B$3))),'Rates from Ireland Fedex Econom'!J6) -> 83 | K7: =IF(ISNUMBER('Rates from Ireland Fedex Econom'!K6),_xlfn.CEILING.MATH('Rates from Ireland Fedex Econom'!K6,1)+(IF($A7="EU",Variables!$B$6,IF($A7="N/A",0,Variables!$B$3))),'Rates from Ireland Fedex Econom'!K6) -> 87 | L7: =IF(ISNUMBER('Rates from Ireland Fedex Econom'!L6),_xlfn.CEILING.MATH('Rates from Ireland Fedex Econom'!L6,1)+(IF($A7="EU",Variables!$B$6,IF($A7="N/A",0,Variables!$B$3))),'Rates from Ireland Fedex Econom'!L6) -> 87 | ... N7: =IF(ISNUMBER('Rates from Ireland Fedex Econom'!N6),_xlfn.CEILING.MATH('Rates from Ireland Fedex Econom'!N6,1)+(IF($A7="EU",Variables!$B$6,IF($A7="N/A",0,Variables!$B$3))),'Rates from Ireland Fedex Econom'!N6) -> 114 | O7: =IF('Rates from Ireland Fedex Econom'!O6="","",'Rates from Ireland Fedex Econom'!O6) -> 6 Days | P7: =IF('Rates from Ireland Fedex Econom'!P6="","",'Rates from Ireland Fedex Econom'!P6) -> 8 Days | Q7: =IF('Rates from Ireland Fedex Econom'!Q6="","",'Rates from Ireland Fedex Econom'!Q6) -> 80 | R7: =IF('Rates from Ireland Fedex Econom'!R6="","",'Rates from Ireland Fedex Econom'!R6) -> 4/5* | S7: =IF('Rates from Ireland Fedex Econom'!S6="","",'Rates from Ireland Fedex Econom'!S6) -> FedEx Economy | T7: =IF('Rates from Ireland Fedex Econom'!T6="","",'Rates from Ireland Fedex Econom'!T6) -> Economy
A8: =IF('Rates from Ireland Fedex Econom'!A7="","",'Rates from Ireland Fedex Econom'!A7) -> EU | B8: =IF('Rates from Ireland Fedex Econom'!B7="","",'Rates from Ireland Fedex Econom'!B7) -> Ireland | C8: =IF('Rates from Ireland Fedex Econom'!C7="","",'Rates from Ireland Fedex Econom'!C7) -> Angola | D8: =IF(ISNUMBER('Rates from Ireland Fedex Econom'!D7),_xlfn.CEILING.MATH('Rates from Ireland Fedex Econom'!D7,1)+(IF($A8="EU",Variables!$B$5,IF($A8="N/A",0,Variables!$B$2))),'Rates from Ireland Fedex Econom'!D7) -> 62 | E8: =IF(ISNUMBER('Rates from Ireland Fedex Econom'!E7),_xlfn.CEILING.MATH('Rates from Ireland Fedex Econom'!E7,1)+(IF($A8="EU",Variables!$B$6,IF($A8="N/A",0,Variables!$B$3))),'Rates from Ireland Fedex Econom'!E7) -> 79 | F8: =IF(ISNUMBER('Rates from Ireland Fedex Econom'!F7),_xlfn.CEILING.MATH('Rates from Ireland Fedex Econom'!F7,1)+(IF($A8="EU",Variables!$B$6,IF($A8="N/A",0,Variables!$B$3))),'Rates from Ireland Fedex Econom'!F7) -> 83 | G8: =IF(ISNUMBER('Rates from Ireland Fedex Econom'!G7),_xlfn.CEILING.MATH('Rates from Ireland Fedex Econom'!G7,1)+(IF($A8="EU",Variables!$B$6,IF($A8="N/A",0,Variables!$B$3))),'Rates from Ireland Fedex Econom'!G7) -> 98 | H8: =IF(ISNUMBER('Rates from Ireland Fedex Econom'!H7),_xlfn.CEILING.MATH('Rates from Ireland Fedex Econom'!H7,1)+(IF($A8="EU",Variables!$B$6,IF($A8="N/A",0,Variables!$B$3))),'Rates from Ireland Fedex Econom'!H7) -> 120 | I8: =IF(ISNUMBER('Rates from Ireland Fedex Econom'!I7),_xlfn.CEILING.MATH('Rates from Ireland Fedex Econom'!I7,1)+(IF($A8="EU",Variables!$B$6,IF($A8="N/A",0,Variables!$B$3))),'Rates from Ireland Fedex Econom'!I7) -> 207 | J8: =IF(ISNUMBER('Rates from Ireland Fedex Econom'!J7),_xlfn.CEILING.MATH('Rates from Ireland Fedex Econom'!J7,1)+(IF($A8="EU",Variables!$B$6,IF($A8="N/A",0,Variables!$B$3))),'Rates from Ireland Fedex Econom'!J7) -> 257 | K8: =IF(ISNUMBER('Rates from Ireland Fedex Econom'!K7),_xlfn.CEILING.MATH('Rates from Ireland Fedex Econom'!K7,1)+(IF($A8="EU",Variables!$B$6,IF($A8="N/A",0,Variables!$B$3))),'Rates from Ireland Fedex Econom'!K7) -> 307 | L8: =IF(ISNUMBER('Rates from Ireland Fedex Econom'!L7),_xlfn.CEILING.MATH('Rates from Ireland Fedex Econom'!L7,1)+(IF($A8="EU",Variables!$B$6,IF($A8="N/A",0,Variables!$B$3))),'Rates from Ireland Fedex Econom'!L7) -> 140 | ... N8: =IF(ISNUMBER('Rates from Ireland Fedex Econom'!N7),_xlfn.CEILING.MATH('Rates from Ireland Fedex Econom'!N7,1)+(IF($A8="EU",Variables!$B$6,IF($A8="N/A",0,Variables!$B$3))),'Rates from Ireland Fedex Econom'!N7) -> 376 | O8: =IF('Rates from Ireland Fedex Econom'!O7="","",'Rates from Ireland Fedex Econom'!O7) -> 2-4 Days | P8: =IF('Rates from Ireland Fedex Econom'!P7="","",'Rates from Ireland Fedex Econom'!P7) -> 2-5 Days | Q8: =IF('Rates from Ireland Fedex Econom'!Q7="","",'Rates from Ireland Fedex Econom'!Q7) -> 80 | R8: =IF('Rates from Ireland Fedex Econom'!R7="","",'Rates from Ireland Fedex Econom'!R7) -> 4/5* | S8: =IF('Rates from Ireland Fedex Econom'!S7="","",'Rates from Ireland Fedex Econom'!S7) -> FedEx Economy | T8: =IF('Rates from Ireland Fedex Econom'!T7="","",'Rates from Ireland Fedex Econom'!T7) -> Economy
A9: =IF('Rates from Ireland Fedex Econom'!A8="","",'Rates from Ireland Fedex Econom'!A8) -> EU | B9: =IF('Rates from Ireland Fedex Econom'!B8="","",'Rates from Ireland Fedex Econom'!B8) -> Ireland | C9: =IF('Rates from Ireland Fedex Econom'!C8="","",'Rates from Ireland Fedex Econom'!C8) -> Anguilla | D9: =IF(ISNUMBER('Rates from Ireland Fedex Econom'!D8),_xlfn.CEILING.MATH('Rates from Ireland Fedex Econom'!D8,1)+(IF($A9="EU",Variables!$B$5,IF($A9="N/A",0,Variables!$B$2))),'Rates from Ireland Fedex Econom'!D8) -> 58 | E9: =IF(ISNUMBER('Rates from Ireland Fedex Econom'!E8),_xlfn.CEILING.MATH('Rates from Ireland Fedex Econom'!E8,1)+(IF($A9="EU",Variables!$B$6,IF($A9="N/A",0,Variables!$B$3))),'Rates from Ireland Fedex Econom'!E8) -> 74 | F9: =IF(ISNUMBER('Rates from Ireland Fedex Econom'!F8),_xlfn.CEILING.MATH('Rates from Ireland Fedex Econom'!F8,1)+(IF($A9="EU",Variables!$B$6,IF($A9="N/A",0,Variables!$B$3))),'Rates from Ireland Fedex Econom'!F8) -> 78 | G9: =IF(ISNUMBER('Rates from Ireland Fedex Econom'!G8),_xlfn.CEILING.MATH('Rates from Ireland Fedex Econom'!G8,1)+(IF($A9="EU",Variables!$B$6,IF($A9="N/A",0,Variables!$B$3))),'Rates from Ireland Fedex Econom'!G8) -> 90 | H9: =IF(ISNUMBER('Rates from Ireland Fedex Econom'!H8),_xlfn.CEILING.MATH('Rates from Ireland Fedex Econom'!H8,1)+(IF($A9="EU",Variables!$B$6,IF($A9="N/A",0,Variables!$B$3))),'Rates from Ireland Fedex Econom'!H8) -> 107 | I9: =IF(ISNUMBER('Rates from Ireland Fedex Econom'!I8),_xlfn.CEILING.MATH('Rates from Ireland Fedex Econom'!I8,1)+(IF($A9="EU",Variables!$B$6,IF($A9="N/A",0,Variables!$B$3))),'Rates from Ireland Fedex Econom'!I8) -> 188 | J9: =IF(ISNUMBER('Rates from Ireland Fedex Econom'!J8),_xlfn.CEILING.MATH('Rates from Ireland Fedex Econom'!J8,1)+(IF($A9="EU",Variables!$B$6,IF($A9="N/A",0,Variables!$B$3))),'Rates from Ireland Fedex Econom'!J8) -> 239 | K9: =IF(ISNUMBER('Rates from Ireland Fedex Econom'!K8),_xlfn.CEILING.MATH('Rates from Ireland Fedex Econom'!K8,1)+(IF($A9="EU",Variables!$B$6,IF($A9="N/A",0,Variables!$B$3))),'Rates from Ireland Fedex Econom'!K8) -> 258 | L9: =IF(ISNUMBER('Rates from Ireland Fedex Econom'!L8),_xlfn.CEILING.MATH('Rates from Ireland Fedex Econom'!L8,1)+(IF($A9="EU",Variables!$B$6,IF($A9="N/A",0,Variables!$B$3))),'Rates from Ireland Fedex Econom'!L8) -> 127 | ... N9: =IF(ISNUMBER('Rates from Ireland Fedex Econom'!N8),_xlfn.CEILING.MATH('Rates from Ireland Fedex Econom'!N8,1)+(IF($A9="EU",Variables!$B$6,IF($A9="N/A",0,Variables!$B$3))),'Rates from Ireland Fedex Econom'!N8) -> 351 | O9: =IF('Rates from Ireland Fedex Econom'!O8="","",'Rates from Ireland Fedex Econom'!O8) -> 7 Days | P9: =IF('Rates from Ireland Fedex Econom'!P8="","",'Rates from Ireland Fedex Econom'!P8) -> 12-14 Days | Q9: =IF('Rates from Ireland Fedex Econom'!Q8="","",'Rates from Ireland Fedex Econom'!Q8) -> 80 | R9: =IF('Rates from Ireland Fedex Econom'!R8="","",'Rates from Ireland Fedex Econom'!R8) -> 4/5* | S9: =IF('Rates from Ireland Fedex Econom'!S8="","",'Rates from Ireland Fedex Econom'!S8) -> FedEx Economy | T9: =IF('Rates from Ireland Fedex Econom'!T8="","",'Rates from Ireland Fedex Econom'!T8) -> Economy
A10: =IF('Rates from Ireland Fedex Econom'!A9="","",'Rates from Ireland Fedex Econom'!A9) -> EU | B10: =IF('Rates from Ireland Fedex Econom'!B9="","",'Rates from Ireland Fedex Econom'!B9) -> Ireland | C10: =IF('Rates from Ireland Fedex Econom'!C9="","",'Rates from Ireland Fedex Econom'!C9) -> Antigua and Barbuda | D10: =IF(ISNUMBER('Rates from Ireland Fedex Econom'!D9),_xlfn.CEILING.MATH('Rates from Ireland Fedex Econom'!D9,1)+(IF($A10="EU",Variables!$B$5,IF($A10="N/A",0,Variables!$B$2))),'Rates from Ireland Fedex Econom'!D9) -> 58 | E10: =IF(ISNUMBER('Rates from Ireland Fedex Econom'!E9),_xlfn.CEILING.MATH('Rates from Ireland Fedex Econom'!E9,1)+(IF($A10="EU",Variables!$B$6,IF($A10="N/A",0,Variables!$B$3))),'Rates from Ireland Fedex Econom'!E9) -> 74 | F10: =IF(ISNUMBER('Rates from Ireland Fedex Econom'!F9),_xlfn.CEILING.MATH('Rates from Ireland Fedex Econom'!F9,1)+(IF($A10="EU",Variables!$B$6,IF($A10="N/A",0,Variables!$B$3))),'Rates from Ireland Fedex Econom'!F9) -> 78 | G10: =IF(ISNUMBER('Rates from Ireland Fedex Econom'!G9),_xlfn.CEILING.MATH('Rates from Ireland Fedex Econom'!G9,1)+(IF($A10="EU",Variables!$B$6,IF($A10="N/A",0,Variables!$B$3))),'Rates from Ireland Fedex Econom'!G9) -> 90 | H10: =IF(ISNUMBER('Rates from Ireland Fedex Econom'!H9),_xlfn.CEILING.MATH('Rates from Ireland Fedex Econom'!H9,1)+(IF($A10="EU",Variables!$B$6,IF($A10="N/A",0,Variables!$B$3))),'Rates from Ireland Fedex Econom'!H9) -> 107 | I10: =IF(ISNUMBER('Rates from Ireland Fedex Econom'!I9),_xlfn.CEILING.MATH('Rates from Ireland Fedex Econom'!I9,1)+(IF($A10="EU",Variables!$B$6,IF($A10="N/A",0,Variables!$B$3))),'Rates from Ireland Fedex Econom'!I9) -> 188 | J10: =IF(ISNUMBER('Rates from Ireland Fedex Econom'!J9),_xlfn.CEILING.MATH('Rates from Ireland Fedex Econom'!J9,1)+(IF($A10="EU",Variables!$B$6,IF($A10="N/A",0,Variables!$B$3))),'Rates from Ireland Fedex Econom'!J9) -> 239 | K10: =IF(ISNUMBER('Rates from Ireland Fedex Econom'!K9),_xlfn.CEILING.MATH('Rates from Ireland Fedex Econom'!K9,1)+(IF($A10="EU",Variables!$B$6,IF($A10="N/A",0,Variables!$B$3))),'Rates from Ireland Fedex Econom'!K9) -> 258 | L10: =IF(ISNUMBER('Rates from Ireland Fedex Econom'!L9),_xlfn.CEILING.MATH('Rates from Ireland Fedex Econom'!L9,1)+(IF($A10="EU",Variables!$B$6,IF($A10="N/A",0,Variables!$B$3))),'Rates from Ireland Fedex Econom'!L9) -> 127 | ... N10: =IF(ISNUMBER('Rates from Ireland Fedex Econom'!N9),_xlfn.CEILING.MATH('Rates from Ireland Fedex Econom'!N9,1)+(IF($A10="EU",Variables!$B$6,IF($A10="N/A",0,Variables!$B$3))),'Rates from Ireland Fedex Econom'!N9) -> 351 | O10: =IF('Rates from Ireland Fedex Econom'!O9="","",'Rates from Ireland Fedex Econom'!O9) -> 5 Days | P10: =IF('Rates from Ireland Fedex Econom'!P9="","",'Rates from Ireland Fedex Econom'!P9) -> 8 Days | Q10: =IF('Rates from Ireland Fedex Econom'!Q9="","",'Rates from Ireland Fedex Econom'!Q9) -> 80 | R10: =IF('Rates from Ireland Fedex Econom'!R9="","",'Rates from Ireland Fedex Econom'!R9) -> 4/5* | S10: =IF('Rates from Ireland Fedex Econom'!S9="","",'Rates from Ireland Fedex Econom'!S9) -> FedEx Economy | T10: =IF('Rates from Ireland Fedex Econom'!T9="","",'Rates from Ireland Fedex Econom'!T9) -> Economy
A11: =IF('Rates from Ireland Fedex Econom'!A10="","",'Rates from Ireland Fedex Econom'!A10) -> EU | B11: =IF('Rates from Ireland Fedex Econom'!B10="","",'Rates from Ireland Fedex Econom'!B10) -> Ireland | C11: =IF('Rates from Ireland Fedex Econom'!C10="","",'Rates from Ireland Fedex Econom'!C10) -> Argentina | D11: =IF(ISNUMBER('Rates from Ireland Fedex Econom'!D10),_xlfn.CEILING.MATH('Rates from Ireland Fedex Econom'!D10,1)+(IF($A11="EU",Variables!$B$5,IF($A11="N/A",0,Variables!$B$2))),'Rates from Ireland Fedex Econom'!D10) -> 58 | E11: =IF(ISNUMBER('Rates from Ireland Fedex Econom'!E10),_xlfn.CEILING.MATH('Rates from Ireland Fedex Econom'!E10,1)+(IF($A11="EU",Variables!$B$6,IF($A11="N/A",0,Variables!$B$3))),'Rates from Ireland Fedex Econom'!E10) -> 74 | F11: =IF(ISNUMBER('Rates from Ireland Fedex Econom'!F10),_xlfn.CEILING.MATH('Rates from Ireland Fedex Econom'!F10,1)+(IF($A11="EU",Variables!$B$6,IF($A11="N/A",0,Variables!$B$3))),'Rates from Ireland Fedex Econom'!F10) -> 78 | G11: =IF(ISNUMBER('Rates from Ireland Fedex Econom'!G10),_xlfn.CEILING.MATH('Rates from Ireland Fedex Econom'!G10,1)+(IF($A11="EU",Variables!$B$6,IF($A11="N/A",0,Variables!$B$3))),'Rates from Ireland Fedex Econom'!G10) -> 90 | H11: =IF(ISNUMBER('Rates from Ireland Fedex Econom'!H10),_xlfn.CEILING.MATH('Rates from Ireland Fedex Econom'!H10,1)+(IF($A11="EU",Variables!$B$6,IF($A11="N/A",0,Variables!$B$3))),'Rates from Ireland Fedex Econom'!H10) -> 107 | I11: =IF(ISNUMBER('Rates from Ireland Fedex Econom'!I10),_xlfn.CEILING.MATH('Rates from Ireland Fedex Econom'!I10,1)+(IF($A11="EU",Variables!$B$6,IF($A11="N/A",0,Variables!$B$3))),'Rates from Ireland Fedex Econom'!I10) -> 188 | J11: =IF(ISNUMBER('Rates from Ireland Fedex Econom'!J10),_xlfn.CEILING.MATH('Rates from Ireland Fedex Econom'!J10,1)+(IF($A11="EU",Variables!$B$6,IF($A11="N/A",0,Variables!$B$3))),'Rates from Ireland Fedex Econom'!J10) -> 239 | K11: =IF(ISNUMBER('Rates from Ireland Fedex Econom'!K10),_xlfn.CEILING.MATH('Rates from Ireland Fedex Econom'!K10,1)+(IF($A11="EU",Variables!$B$6,IF($A11="N/A",0,Variables!$B$3))),'Rates from Ireland Fedex Econom'!K10) -> 258 | L11: =IF(ISNUMBER('Rates from Ireland Fedex Econom'!L10),_xlfn.CEILING.MATH('Rates from Ireland Fedex Econom'!L10,1)+(IF($A11="EU",Variables!$B$6,IF($A11="N/A",0,Variables!$B$3))),'Rates from Ireland Fedex Econom'!L10) -> 127 | ... N11: =IF(ISNUMBER('Rates from Ireland Fedex Econom'!N10),_xlfn.CEILING.MATH('Rates from Ireland Fedex Econom'!N10,1)+(IF($A11="EU",Variables!$B$6,IF($A11="N/A",0,Variables!$B$3))),'Rates from Ireland Fedex Econom'!N10) -> 351 | O11: =IF('Rates from Ireland Fedex Econom'!O10="","",'Rates from Ireland Fedex Econom'!O10) -> 5 Days | P11: =IF('Rates from Ireland Fedex Econom'!P10="","",'Rates from Ireland Fedex Econom'!P10) -> 8 Days | Q11: =IF('Rates from Ireland Fedex Econom'!Q10="","",'Rates from Ireland Fedex Econom'!Q10) -> 80 | R11: =IF('Rates from Ireland Fedex Econom'!R10="","",'Rates from Ireland Fedex Econom'!R10) -> 4/5* | S11: =IF('Rates from Ireland Fedex Econom'!S10="","",'Rates from Ireland Fedex Econom'!S10) -> FedEx Economy | T11: =IF('Rates from Ireland Fedex Econom'!T10="","",'Rates from Ireland Fedex Econom'!T10) -> Economy
A12: =IF('Rates from Ireland Fedex Econom'!A11="","",'Rates from Ireland Fedex Econom'!A11) -> EU | B12: =IF('Rates from Ireland Fedex Econom'!B11="","",'Rates from Ireland Fedex Econom'!B11) -> Ireland | C12: =IF('Rates from Ireland Fedex Econom'!C11="","",'Rates from Ireland Fedex Econom'!C11) -> Armenia | D12: =IF(ISNUMBER('Rates from Ireland Fedex Econom'!D11),_xlfn.CEILING.MATH('Rates from Ireland Fedex Econom'!D11,1)+(IF($A12="EU",Variables!$B$5,IF($A12="N/A",0,Variables!$B$2))),'Rates from Ireland Fedex Econom'!D11) -> 52 | E12: =IF(ISNUMBER('Rates from Ireland Fedex Econom'!E11),_xlfn.CEILING.MATH('Rates from Ireland Fedex Econom'!E11,1)+(IF($A12="EU",Variables!$B$6,IF($A12="N/A",0,Variables!$B$3))),'Rates from Ireland Fedex Econom'!E11) -> 68 | F12: =IF(ISNUMBER('Rates from Ireland Fedex Econom'!F11),_xlfn.CEILING.MATH('Rates from Ireland Fedex Econom'!F11,1)+(IF($A12="EU",Variables!$B$6,IF($A12="N/A",0,Variables!$B$3))),'Rates from Ireland Fedex Econom'!F11) -> 71 | G12: =IF(ISNUMBER('Rates from Ireland Fedex Econom'!G11),_xlfn.CEILING.MATH('Rates from Ireland Fedex Econom'!G11,1)+(IF($A12="EU",Variables!$B$6,IF($A12="N/A",0,Variables!$B$3))),'Rates from Ireland Fedex Econom'!G11) -> 82 | H12: =IF(ISNUMBER('Rates from Ireland Fedex Econom'!H11),_xlfn.CEILING.MATH('Rates from Ireland Fedex Econom'!H11,1)+(IF($A12="EU",Variables!$B$6,IF($A12="N/A",0,Variables!$B$3))),'Rates from Ireland Fedex Econom'!H11) -> 102 | I12: =IF(ISNUMBER('Rates from Ireland Fedex Econom'!I11),_xlfn.CEILING.MATH('Rates from Ireland Fedex Econom'!I11,1)+(IF($A12="EU",Variables!$B$6,IF($A12="N/A",0,Variables!$B$3))),'Rates from Ireland Fedex Econom'!I11) -> 152 | J12: =IF(ISNUMBER('Rates from Ireland Fedex Econom'!J11),_xlfn.CEILING.MATH('Rates from Ireland Fedex Econom'!J11,1)+(IF($A12="EU",Variables!$B$6,IF($A12="N/A",0,Variables!$B$3))),'Rates from Ireland Fedex Econom'!J11) -> 185 | K12: =IF(ISNUMBER('Rates from Ireland Fedex Econom'!K11),_xlfn.CEILING.MATH('Rates from Ireland Fedex Econom'!K11,1)+(IF($A12="EU",Variables!$B$6,IF($A12="N/A",0,Variables!$B$3))),'Rates from Ireland Fedex Econom'!K11) -> 221 | L12: =IF(ISNUMBER('Rates from Ireland Fedex Econom'!L11),_xlfn.CEILING.MATH('Rates from Ireland Fedex Econom'!L11,1)+(IF($A12="EU",Variables!$B$6,IF($A12="N/A",0,Variables!$B$3))),'Rates from Ireland Fedex Econom'!L11) -> 132 | ... N12: =IF(ISNUMBER('Rates from Ireland Fedex Econom'!N11),_xlfn.CEILING.MATH('Rates from Ireland Fedex Econom'!N11,1)+(IF($A12="EU",Variables!$B$6,IF($A12="N/A",0,Variables!$B$3))),'Rates from Ireland Fedex Econom'!N11) -> 291 | O12: =IF('Rates from Ireland Fedex Econom'!O11="","",'Rates from Ireland Fedex Econom'!O11) -> 3 Days | P12: =IF('Rates from Ireland Fedex Econom'!P11="","",'Rates from Ireland Fedex Econom'!P11) -> 3-4 Days | Q12: =IF('Rates from Ireland Fedex Econom'!Q11="","",'Rates from Ireland Fedex Econom'!Q11) -> 80 | R12: =IF('Rates from Ireland Fedex Econom'!R11="","",'Rates from Ireland Fedex Econom'!R11) -> 4/5* | S12: =IF('Rates from Ireland Fedex Econom'!S11="","",'Rates from Ireland Fedex Econom'!S11) -> FedEx Economy | T12: =IF('Rates from Ireland Fedex Econom'!T11="","",'Rates from Ireland Fedex Econom'!T11) -> Economy
A13: =IF('Rates from Ireland Fedex Econom'!A12="","",'Rates from Ireland Fedex Econom'!A12) -> EU | B13: =IF('Rates from Ireland Fedex Econom'!B12="","",'Rates from Ireland Fedex Econom'!B12) -> Ireland | C13: =IF('Rates from Ireland Fedex Econom'!C12="","",'Rates from Ireland Fedex Econom'!C12) -> Aruba (Netherlands) | D13: =IF(ISNUMBER('Rates from Ireland Fedex Econom'!D12),_xlfn.CEILING.MATH('Rates from Ireland Fedex Econom'!D12,1)+(IF($A13="EU",Variables!$B$5,IF($A13="N/A",0,Variables!$B$2))),'Rates from Ireland Fedex Econom'!D12) -> 58 | E13: =IF(ISNUMBER('Rates from Ireland Fedex Econom'!E12),_xlfn.CEILING.MATH('Rates from Ireland Fedex Econom'!E12,1)+(IF($A13="EU",Variables!$B$6,IF($A13="N/A",0,Variables!$B$3))),'Rates from Ireland Fedex Econom'!E12) -> 74 | F13: =IF(ISNUMBER('Rates from Ireland Fedex Econom'!F12),_xlfn.CEILING.MATH('Rates from Ireland Fedex Econom'!F12,1)+(IF($A13="EU",Variables!$B$6,IF($A13="N/A",0,Variables!$B$3))),'Rates from Ireland Fedex Econom'!F12) -> 78 | G13: =IF(ISNUMBER('Rates from Ireland Fedex Econom'!G12),_xlfn.CEILING.MATH('Rates from Ireland Fedex Econom'!G12,1)+(IF($A13="EU",Variables!$B$6,IF($A13="N/A",0,Variables!$B$3))),'Rates from Ireland Fedex Econom'!G12) -> 90 | H13: =IF(ISNUMBER('Rates from Ireland Fedex Econom'!H12),_xlfn.CEILING.MATH('Rates from Ireland Fedex Econom'!H12,1)+(IF($A13="EU",Variables!$B$6,IF($A13="N/A",0,Variables!$B$3))),'Rates from Ireland Fedex Econom'!H12) -> 107 | I13: =IF(ISNUMBER('Rates from Ireland Fedex Econom'!I12),_xlfn.CEILING.MATH('Rates from Ireland Fedex Econom'!I12,1)+(IF($A13="EU",Variables!$B$6,IF($A13="N/A",0,Variables!$B$3))),'Rates from Ireland Fedex Econom'!I12) -> 188 | J13: =IF(ISNUMBER('Rates from Ireland Fedex Econom'!J12),_xlfn.CEILING.MATH('Rates from Ireland Fedex Econom'!J12,1)+(IF($A13="EU",Variables!$B$6,IF($A13="N/A",0,Variables!$B$3))),'Rates from Ireland Fedex Econom'!J12) -> 239 | K13: =IF(ISNUMBER('Rates from Ireland Fedex Econom'!K12),_xlfn.CEILING.MATH('Rates from Ireland Fedex Econom'!K12,1)+(IF($A13="EU",Variables!$B$6,IF($A13="N/A",0,Variables!$B$3))),'Rates from Ireland Fedex Econom'!K12) -> 258 | L13: =IF(ISNUMBER('Rates from Ireland Fedex Econom'!L12),_xlfn.CEILING.MATH('Rates from Ireland Fedex Econom'!L12,1)+(IF($A13="EU",Variables!$B$6,IF($A13="N/A",0,Variables!$B$3))),'Rates from Ireland Fedex Econom'!L12) -> 127 | ... N13: =IF(ISNUMBER('Rates from Ireland Fedex Econom'!N12),_xlfn.CEILING.MATH('Rates from Ireland Fedex Econom'!N12,1)+(IF($A13="EU",Variables!$B$6,IF($A13="N/A",0,Variables!$B$3))),'Rates from Ireland Fedex Econom'!N12) -> 351 | O13: =IF('Rates from Ireland Fedex Econom'!O12="","",'Rates from Ireland Fedex Econom'!O12) -> 5 Days | P13: =IF('Rates from Ireland Fedex Econom'!P12="","",'Rates from Ireland Fedex Econom'!P12) -> 8 Days | Q13: =IF('Rates from Ireland Fedex Econom'!Q12="","",'Rates from Ireland Fedex Econom'!Q12) -> 80 | R13: =IF('Rates from Ireland Fedex Econom'!R12="","",'Rates from Ireland Fedex Econom'!R12) -> 4/5* | S13: =IF('Rates from Ireland Fedex Econom'!S12="","",'Rates from Ireland Fedex Econom'!S12) -> FedEx Economy | T13: =IF('Rates from Ireland Fedex Econom'!T12="","",'Rates from Ireland Fedex Econom'!T12) -> Economy
A14: =IF('Rates from Ireland Fedex Econom'!A13="","",'Rates from Ireland Fedex Econom'!A13) -> EU | B14: =IF('Rates from Ireland Fedex Econom'!B13="","",'Rates from Ireland Fedex Econom'!B13) -> Ireland | C14: =IF('Rates from Ireland Fedex Econom'!C13="","",'Rates from Ireland Fedex Econom'!C13) -> Australia | D14: =IF(ISNUMBER('Rates from Ireland Fedex Econom'!D13),_xlfn.CEILING.MATH('Rates from Ireland Fedex Econom'!D13,1)+(IF($A14="EU",Variables!$B$5,IF($A14="N/A",0,Variables!$B$2))),'Rates from Ireland Fedex Econom'!D13) -> 78 | E14: =IF(ISNUMBER('Rates from Ireland Fedex Econom'!E13),_xlfn.CEILING.MATH('Rates from Ireland Fedex Econom'!E13,1)+(IF($A14="EU",Variables!$B$6,IF($A14="N/A",0,Variables!$B$3))),'Rates from Ireland Fedex Econom'!E13) -> 96 | F14: =IF(ISNUMBER('Rates from Ireland Fedex Econom'!F13),_xlfn.CEILING.MATH('Rates from Ireland Fedex Econom'!F13,1)+(IF($A14="EU",Variables!$B$6,IF($A14="N/A",0,Variables!$B$3))),'Rates from Ireland Fedex Econom'!F13) -> 103 | G14: =IF(ISNUMBER('Rates from Ireland Fedex Econom'!G13),_xlfn.CEILING.MATH('Rates from Ireland Fedex Econom'!G13,1)+(IF($A14="EU",Variables!$B$6,IF($A14="N/A",0,Variables!$B$3))),'Rates from Ireland Fedex Econom'!G13) -> 132 | H14: =IF(ISNUMBER('Rates from Ireland Fedex Econom'!H13),_xlfn.CEILING.MATH('Rates from Ireland Fedex Econom'!H13,1)+(IF($A14="EU",Variables!$B$6,IF($A14="N/A",0,Variables!$B$3))),'Rates from Ireland Fedex Econom'!H13) -> 168 | I14: =IF(ISNUMBER('Rates from Ireland Fedex Econom'!I13),_xlfn.CEILING.MATH('Rates from Ireland Fedex Econom'!I13,1)+(IF($A14="EU",Variables!$B$6,IF($A14="N/A",0,Variables!$B$3))),'Rates from Ireland Fedex Econom'!I13) -> 233 | J14: =IF(ISNUMBER('Rates from Ireland Fedex Econom'!J13),_xlfn.CEILING.MATH('Rates from Ireland Fedex Econom'!J13,1)+(IF($A14="EU",Variables!$B$6,IF($A14="N/A",0,Variables!$B$3))),'Rates from Ireland Fedex Econom'!J13) -> 293 | K14: =IF(ISNUMBER('Rates from Ireland Fedex Econom'!K13),_xlfn.CEILING.MATH('Rates from Ireland Fedex Econom'!K13,1)+(IF($A14="EU",Variables!$B$6,IF($A14="N/A",0,Variables!$B$3))),'Rates from Ireland Fedex Econom'!K13) -> 352 | L14: =IF(ISNUMBER('Rates from Ireland Fedex Econom'!L13),_xlfn.CEILING.MATH('Rates from Ireland Fedex Econom'!L13,1)+(IF($A14="EU",Variables!$B$6,IF($A14="N/A",0,Variables!$B$3))),'Rates from Ireland Fedex Econom'!L13) -> 188 | ... N14: =IF(ISNUMBER('Rates from Ireland Fedex Econom'!N13),_xlfn.CEILING.MATH('Rates from Ireland Fedex Econom'!N13,1)+(IF($A14="EU",Variables!$B$6,IF($A14="N/A",0,Variables!$B$3))),'Rates from Ireland Fedex Econom'!N13) -> 432 | O14: =IF('Rates from Ireland Fedex Econom'!O13="","",'Rates from Ireland Fedex Econom'!O13) -> 5 Days | P14: =IF('Rates from Ireland Fedex Econom'!P13="","",'Rates from Ireland Fedex Econom'!P13) -> 8 Days | Q14: =IF('Rates from Ireland Fedex Econom'!Q13="","",'Rates from Ireland Fedex Econom'!Q13) -> 80 | R14: =IF('Rates from Ireland Fedex Econom'!R13="","",'Rates from Ireland Fedex Econom'!R13) -> 4/5* | S14: =IF('Rates from Ireland Fedex Econom'!S13="","",'Rates from Ireland Fedex Econom'!S13) -> FedEx Economy | T14: =IF('Rates from Ireland Fedex Econom'!T13="","",'Rates from Ireland Fedex Econom'!T13) -> Economy
... A251: =IF('Rates from Ireland Fedex Econom'!A250="","",'Rates from Ireland Fedex Econom'!A250) -> EU | B251: =IF('Rates from Ireland Fedex Econom'!B250="","",'Rates from Ireland Fedex Econom'!B250) -> Ireland | C251: =IF('Rates from Ireland Fedex Econom'!C250="","",'Rates from Ireland Fedex Econom'!C250) -> Zimbabwe | D251: =IF(ISNUMBER('Rates from Ireland Fedex Econom'!D250),_xlfn.CEILING.MATH('Rates from Ireland Fedex Econom'!D250,1)+(IF($A251="EU",Variables!$B$5,IF($A251="N/A",0,Variables!$B$2))),'Rates from Ireland Fedex Econom'!D250) -> 65 | E251: =IF(ISNUMBER('Rates from Ireland Fedex Econom'!E250),_xlfn.CEILING.MATH('Rates from Ireland Fedex Econom'!E250,1)+(IF($A251="EU",Variables!$B$6,IF($A251="N/A",0,Variables!$B$3))),'Rates from Ireland Fedex Econom'!E250) -> 79 | F251: =IF(ISNUMBER('Rates from Ireland Fedex Econom'!F250),_xlfn.CEILING.MATH('Rates from Ireland Fedex Econom'!F250,1)+(IF($A251="EU",Variables!$B$6,IF($A251="N/A",0,Variables!$B$3))),'Rates from Ireland Fedex Econom'!F250) -> 83 | G251: =IF(ISNUMBER('Rates from Ireland Fedex Econom'!G250),_xlfn.CEILING.MATH('Rates from Ireland Fedex Econom'!G250,1)+(IF($A251="EU",Variables!$B$6,IF($A251="N/A",0,Variables!$B$3))),'Rates from Ireland Fedex Econom'!G250) -> 98 | H251: =IF(ISNUMBER('Rates from Ireland Fedex Econom'!H250),_xlfn.CEILING.MATH('Rates from Ireland Fedex Econom'!H250,1)+(IF($A251="EU",Variables!$B$6,IF($A251="N/A",0,Variables!$B$3))),'Rates from Ireland Fedex Econom'!H250) -> 120 | I251: =IF(ISNUMBER('Rates from Ireland Fedex Econom'!I250),_xlfn.CEILING.MATH('Rates from Ireland Fedex Econom'!I250,1)+(IF($A251="EU",Variables!$B$6,IF($A251="N/A",0,Variables!$B$3))),'Rates from Ireland Fedex Econom'!I250) -> 207 | J251: =IF(ISNUMBER('Rates from Ireland Fedex Econom'!J250),_xlfn.CEILING.MATH('Rates from Ireland Fedex Econom'!J250,1)+(IF($A251="EU",Variables!$B$6,IF($A251="N/A",0,Variables!$B$3))),'Rates from Ireland Fedex Econom'!J250) -> 257 | K251: =IF(ISNUMBER('Rates from Ireland Fedex Econom'!K250),_xlfn.CEILING.MATH('Rates from Ireland Fedex Econom'!K250,1)+(IF($A251="EU",Variables!$B$6,IF($A251="N/A",0,Variables!$B$3))),'Rates from Ireland Fedex Econom'!K250) -> 307 | L251: =IF(ISNUMBER('Rates from Ireland Fedex Econom'!L250),_xlfn.CEILING.MATH('Rates from Ireland Fedex Econom'!L250,1)+(IF($A251="EU",Variables!$B$6,IF($A251="N/A",0,Variables!$B$3))),'Rates from Ireland Fedex Econom'!L250) -> 140 | ... N251: =IF(ISNUMBER('Rates from Ireland Fedex Econom'!N250),_xlfn.CEILING.MATH('Rates from Ireland Fedex Econom'!N250,1)+(IF($A251="EU",Variables!$B$6,IF($A251="N/A",0,Variables!$B$3))),'Rates from Ireland Fedex Econom'!N250) -> 376 | O251: =IF('Rates from Ireland Fedex Econom'!O250="","",'Rates from Ireland Fedex Econom'!O250) -> 8-12 Days | P251: =IF('Rates from Ireland Fedex Econom'!P250="","",'Rates from Ireland Fedex Econom'!P250) -> 8-12 Days | Q251: =IF('Rates from Ireland Fedex Econom'!Q250="","",'Rates from Ireland Fedex Econom'!Q250) -> 80 | R251: =IF('Rates from Ireland Fedex Econom'!R250="","",'Rates from Ireland Fedex Econom'!R250) -> 4/5* | S251: =IF('Rates from Ireland Fedex Econom'!S250="","",'Rates from Ireland Fedex Econom'!S250) -> FedEx Economy | T251: =IF('Rates from Ireland Fedex Econom'!T250="","",'Rates from Ireland Fedex Econom'!T250) -> Economy
A1048560: =IF('Rates from Ireland Fedex Econom'!A1048559="","",'Rates from Ireland Fedex Econom'!A1048559)
A1048561: =IF('Rates from Ireland Fedex Econom'!A1048560="","",'Rates from Ireland Fedex Econom'!A1048560)
A1048562: =IF('Rates from Ireland Fedex Econom'!A1048561="","",'Rates from Ireland Fedex Econom'!A1048561)
A1048563: =IF('Rates from Ireland Fedex Econom'!A1048562="","",'Rates from Ireland Fedex Econom'!A1048562)
A1048564: =IF('Rates from Ireland Fedex Econom'!A1048563="","",'Rates from Ireland Fedex Econom'!A1048563)
A1048565: =IF('Rates from Ireland Fedex Econom'!A1048564="","",'Rates from Ireland Fedex Econom'!A1048564)
A1048566: =IF('Rates from Ireland Fedex Econom'!A1048565="","",'Rates from Ireland Fedex Econom'!A1048565)
A1048567: =IF('Rates from Ireland Fedex Econom'!A1048566="","",'Rates from Ireland Fedex Econom'!A1048566)
A1048568: =IF('Rates from Ireland Fedex Econom'!A1048567="","",'Rates from Ireland Fedex Econom'!A1048567)
A1048569: =IF('Rates from Ireland Fedex Econom'!A1048568="","",'Rates from Ireland Fedex Econom'!A1048568)
A1048570: =IF('Rates from Ireland Fedex Econom'!A1048569="","",'Rates from Ireland Fedex Econom'!A1048569)
A1048571: =IF('Rates from Ireland Fedex Econom'!A1048570="","",'Rates from Ireland Fedex Econom'!A1048570)
... A1048576: =IF('Rates from Ireland Fedex Econom'!A1048575="","",'Rates from Ireland Fedex Econom'!A1048575)

Sheet Variables
A1: All
A2: Col D | B2: 40
A3: Col E - N | B3: 50
A4: EU
A5: Col D | B5: 30
A6: Col E - N | B6: 45

Sheet MAx dimension by weight
A1: Weight (kg) | B1: Max Volume (cm³) | C1: Example Dimensions (cm) | F1: Suitcase extra fee to standard rates plus | G1: 20
A2: 1 kg | B2: 5000 cm³ | C2: 20 × 20 × 12.5
A3: 2 kg | B3: 10,000 cm³ | C3: 25 × 25 × 16
A4: 5 kg | B4: 25,000 cm³ | C4: 40 x 30 x 21
A5: 10 kg | B5: 50,000 cm³ | C5: 50 × 40 × 25
A6: 15 kg | B6: 75,000 cm³ | C6: 60 × 50 × 25
A7: 20 kg | B7: 100,000 cm³ | C7: 70 × 50 × 28.6
A8: 25 kg | B8: 125,000 cm³ | C8: 80 × 50 × 31.25
A9: Suitcase 10 kg | B9: 50,000 cm³ | C9: 55 × 35 × 26.4
A10: Suitcase 20 kg | B10: 100,000 cm³ | C10: 70 × 45 × 31.7
A11: Suitcase 30 kg | B11: 150,000 cm³ | C11: 80 × 50 × 37.5

Sheet Instructions
A1: Range D3:N251: Loops through all the cells in this range.
A2: White Cells:
A3: Column D → Add €40 to current value
A4: Columns E to N → Add €50 to current value
A5: Blue Cells:
A6: Column D → Add €30 to current value
A7: Columns E to N → Add €45 to current value
A9: No applied where NO SERVICE or BLANK CELL WITH NO VALUE
A12: Round every value to NEXT round
